Workbook

Sheet 안내
A1: M&A 188건 수집 시트
A3: 원본 | B3: meeting/20261102/MA188_수집시트.csv, MA188_근거.csv (이 파일은 그 CSV를 nbs/ma188_export_xlsx.py로 옮긴 것)
A4: 내용 | B4: CJ ENM 30·Kakao 74·Naver 84, 거래 188건과 근거 4371행. 설계와 결과 해석은 meeting/20261102/주차연구정리_20261102.md
A5: 시트
A6: 요약 | B6: 기업별 수집 상태, 분류 대조표, 손상·편입 시점·금액 대조 집계. 모두 '거래' 시트를 세는 수식
A7: 거래 | B7: 한 행이 한 거래. 1행은 열 묶음, 2행은 열 이름, 3행은 CSV 열 이름이며 3행에 필터가 있다. 거래·기업·날짜·대상회사 열은 고정
A8: 근거 | B8: 한 행이 근거 하나. URL을 누르면 원문이 열린다. '뒷받침하는 열'은 그 근거가 '거래' 시트의 어느 열 값을 뒷받침하는지 적은 것
A9: 열 묶음
A10: 식별 | B10: 거래 번호(C=CJ ENM, K=Kakao, N=Naver), 날짜, 대상회사, 원자료 금액 순위
A11: 분류 요약 (파생) | B11: 원래 열에서 뽑은 값. 거래 형태 (설명란 판정)·거래 형태 (공시 확인)(MA①~⑦ 코드), 형태 변경(변경/같음), 손상 구분(있음 / 없음 (확인) / 식별 불가 / 미확인 / 해당 없음, 근거는 '손상 구분 근거' 열), 금액 대조(일치/불일치/기타), 편입 시점
A12: 원자료 (Capital IQ) | B12: Capital IQ에서 추출한 그대로의 값: 상태, 금액, 매수자, 매도자, 설명란
A13: v4 분야 | B13: v4 파일에서 추가된 12개 분야. Capital IQ 원본에는 없고, 이번 수집에서 확인하지 않았다
A14: 10-19 설명란 판정 | B14: 10-19 분석(nbs/pp_ma_record_audit.py)이 설명란·매수자·매도자 칸을 규칙으로 읽어 붙인 값. 편입 전 표시는 작성자의 배경지식(경영통합 연도 등)에 기댄다
A15: 공시 확인 | B15: 공시·감사보고서로 확인한 거래 형태, 편입 시점, 상태, 금액, 발표일과 메모
A16: 인수 목적·핵심 / 규모 / 주가 이벤트 | B16: 발표 당시 목적, 핵심 여부, 인수 주체·그룹 정점의 규모와 비율, 종목과 처음 알려진 날
A17: 전후 이벤트 / 성과 | B17: 인수 전후 사건, 손상, 대상회사 인수 전후 매출·영업이익, 어닝콜 언급
A18: 수집 | B18: 수집 상태(완료 = 모든 항목을 채움, 부분 = 공개 자료가 없어 비어 있는 항목이 있음)와 수집 일시
A19: 값 표기 | B19: 미확인 = 찾았지만 근거가 없음 · 해당 없음 = 그 거래에 해당하지 않음 · 추정: = 추정한 값
A20: 색 | B20: 거래 형태 (공시 확인)·형태 변경 칸 청록 = 설명란 판정과 거래 형태가 다름 · 손상 구분 빨강 = 있음, 초록 = 없음 (확인), 주황 = 식별 불가·미확인 · 금액 대조 빨강 = 불일치 · 수집 상태 초록 = 완료
A21: 손상 구분 | B21: 있음 = 인수 뒤 손상 확인 · 없음 (확인) = 인수 뒤 영업권·투자주식이 손상 없이 유지됨을 확인 · 식별 불가 = 영업권이 부문 단위로 묶여 이 거래 몫을 알 수 없음 · 미확인 = 확인 기간이 짧거나 비어 판단 자료 부족 · 해당 없음 = 그룹 밖 매수자, 그룹의 매각, 동일지배 합병, 공정가치 금융자산 등 구조상 손상을 따지지 않는 거래
... A23: 행 높이 | B23: 긴 글은 칸 안에서 줄바꿈되고 행 높이는 고정이다. 전체 내용은 셀을 선택해 수식 입력줄에서 보거나 행 높이를 늘려 본다

Sheet 요약
A1: M&A 188건 수집 결과 요약
A2: 모든 수치는 '거래' 시트를 세는 수식이다. '거래' 시트를 고치면 함께 바뀐다.
A4: 기업별 수집 상태
A5: 기업 | B5: 완료 | C5: 부분 | D5: 합계
A6: CJ ENM | B6: =COUNTIFS(거래!$B$4:$B$191,$A6,거래!$BF$4:$BF$191,"완료") | C6: =COUNTIFS(거래!$B$4:$B$191,$A6,거래!$BF$4:$BF$191,"부분") | D6: =SUM(B6:C6)
A7: Kakao | B7: =COUNTIFS(거래!$B$4:$B$191,$A7,거래!$BF$4:$BF$191,"완료") | C7: =COUNTIFS(거래!$B$4:$B$191,$A7,거래!$BF$4:$BF$191,"부분") | D7: =SUM(B7:C7)
A8: Naver | B8: =COUNTIFS(거래!$B$4:$B$191,$A8,거래!$BF$4:$BF$191,"완료") | C8: =COUNTIFS(거래!$B$4:$B$191,$A8,거래!$BF$4:$BF$191,"부분") | D8: =SUM(B8:C8)
A9: 합계 | B9: =SUM(B6:B8) | C9: =SUM(C6:C8) | D9: =SUM(D6:D8)
A11: 거래 형태: 설명란 판정(행) → 공시 확인(열)
A12: 설명란 판정 | B12: MA① 경영권 인수 | C12: MA② 기존 지분 확대 | D12: MA③ 소수지분 매입 | E12: MA④ 그룹 내부 재편 | F12: MA⑤ 그룹의 지분 매각 | G12: MA⑥ 외부자 간 거래 | H12: 합계
A13: MA① 경영권 인수 | B13: =COUNTIFS(거래!$H$4:$H$191,"MA①",거래!$I$4:$I$191,"MA①") | C13: =COUNTIFS(거래!$H$4:$H$191,"MA①",거래!$I$4:$I$191,"MA②") | D13: =COUNTIFS(거래!$H$4:$H$191,"MA①",거래!$I$4:$I$191,"MA③") | E13: =COUNTIFS(거래!$H$4:$H$191,"MA①",거래!$I$4:$I$191,"MA④") | F13: =COUNTIFS(거래!$H$4:$H$191,"MA①",거래!$I$4:$I$191,"MA⑤") | G13: =COUNTIFS(거래!$H$4:$H$191,"MA①",거래!$I$4:$I$191,"MA⑥") | H13: =SUM(B13:G13)
A14: MA② 기존 지분 확대 | B14: =COUNTIFS(거래!$H$4:$H$191,"MA②",거래!$I$4:$I$191,"MA①") | C14: =COUNTIFS(거래!$H$4:$H$191,"MA②",거래!$I$4:$I$191,"MA②") | D14: =COUNTIFS(거래!$H$4:$H$191,"MA②",거래!$I$4:$I$191,"MA③") | E14: =COUNTIFS(거래!$H$4:$H$191,"MA②",거래!$I$4:$I$191,"MA④") | F14: =COUNTIFS(거래!$H$4:$H$191,"MA②",거래!$I$4:$I$191,"MA⑤") | G14: =COUNTIFS(거래!$H$4:$H$191,"MA②",거래!$I$4:$I$191,"MA⑥") | H14: =SUM(B14:G14)
A15: MA③ 소수지분 매입 | B15: =COUNTIFS(거래!$H$4:$H$191,"MA③",거래!$I$4:$I$191,"MA①") | C15: =COUNTIFS(거래!$H$4:$H$191,"MA③",거래!$I$4:$I$191,"MA②") | D15: =COUNTIFS(거래!$H$4:$H$191,"MA③",거래!$I$4:$I$191,"MA③") | E15: =COUNTIFS(거래!$H$4:$H$191,"MA③",거래!$I$4:$I$191,"MA④") | F15: =COUNTIFS(거래!$H$4:$H$191,"MA③",거래!$I$4:$I$191,"MA⑤") | G15: =COUNTIFS(거래!$H$4:$H$191,"MA③",거래!$I$4:$I$191,"MA⑥") | H15: =SUM(B15:G15)
A16: MA④ 그룹 내부 재편 | B16: =COUNTIFS(거래!$H$4:$H$191,"MA④",거래!$I$4:$I$191,"MA①") | C16: =COUNTIFS(거래!$H$4:$H$191,"MA④",거래!$I$4:$I$191,"MA②") | D16: =COUNTIFS(거래!$H$4:$H$191,"MA④",거래!$I$4:$I$191,"MA③") | E16: =COUNTIFS(거래!$H$4:$H$191,"MA④",거래!$I$4:$I$191,"MA④") | F16: =COUNTIFS(거래!$H$4:$H$191,"MA④",거래!$I$4:$I$191,"MA⑤") | G16: =COUNTIFS(거래!$H$4:$H$191,"MA④",거래!$I$4:$I$191,"MA⑥") | H16: =SUM(B16:G16)
A17: MA⑤ 그룹의 지분 매각 | B17: =COUNTIFS(거래!$H$4:$H$191,"MA⑤",거래!$I$4:$I$191,"MA①") | C17: =COUNTIFS(거래!$H$4:$H$191,"MA⑤",거래!$I$4:$I$191,"MA②") | D17: =COUNTIFS(거래!$H$4:$H$191,"MA⑤",거래!$I$4:$I$191,"MA③") | E17: =COUNTIFS(거래!$H$4:$H$191,"MA⑤",거래!$I$4:$I$191,"MA④") | F17: =COUNTIFS(거래!$H$4:$H$191,"MA⑤",거래!$I$4:$I$191,"MA⑤") | G17: =COUNTIFS(거래!$H$4:$H$191,"MA⑤",거래!$I$4:$I$191,"MA⑥") | H17: =SUM(B17:G17)
A18: MA⑥ 외부자 간 거래 | B18: =COUNTIFS(거래!$H$4:$H$191,"MA⑥",거래!$I$4:$I$191,"MA①") | C18: =COUNTIFS(거래!$H$4:$H$191,"MA⑥",거래!$I$4:$I$191,"MA②") | D18: =COUNTIFS(거래!$H$4:$H$191,"MA⑥",거래!$I$4:$I$191,"MA③") | E18: =COUNTIFS(거래!$H$4:$H$191,"MA⑥",거래!$I$4:$I$191,"MA④") | F18: =COUNTIFS(거래!$H$4:$H$191,"MA⑥",거래!$I$4:$I$191,"MA⑤") | G18: =COUNTIFS(거래!$H$4:$H$191,"MA⑥",거래!$I$4:$I$191,"MA⑥") | H18: =SUM(B18:G18)
A19: MA⑦ 매수자 미기재 | B19: =COUNTIFS(거래!$H$4:$H$191,"MA⑦",거래!$I$4:$I$191,"MA①") | C19: =COUNTIFS(거래!$H$4:$H$191,"MA⑦",거래!$I$4:$I$191,"MA②") | D19: =COUNTIFS(거래!$H$4:$H$191,"MA⑦",거래!$I$4:$I$191,"MA③") | E19: =COUNTIFS(거래!$H$4:$H$191,"MA⑦",거래!$I$4:$I$191,"MA④") | F19: =COUNTIFS(거래!$H$4:$H$191,"MA⑦",거래!$I$4:$I$191,"MA⑤") | G19: =COUNTIFS(거래!$H$4:$H$191,"MA⑦",거래!$I$4:$I$191,"MA⑥") | H19: =SUM(B19:G19)
A20: 합계 | B20: =SUM(B13:B19) | C20: =SUM(C13:C19) | D20: =SUM(D13:D19) | E20: =SUM(E13:E19) | F20: =SUM(F13:F19) | G20: =SUM(G13:G19) | H20: =SUM(H13:H19)
A22: 기업별 손상 구분 (188건 전체)
A23: 기업 | B23: 있음 | C23: 없음 (확인) | D23: 식별 불가 | E23: 미확인 | F23: 해당 없음 | G23: 합계
A24: CJ ENM | B24: =COUNTIFS(거래!$B$4:$B$191,$A24,거래!$K$4:$K$191,"있음") | C24: =COUNTIFS(거래!$B$4:$B$191,$A24,거래!$K$4:$K$191,"없음 (확인)") | D24: =COUNTIFS(거래!$B$4:$B$191,$A24,거래!$K$4:$K$191,"식별 불가") | E24: =COUNTIFS(거래!$B$4:$B$191,$A24,거래!$K$4:$K$191,"미확인") | F24: =COUNTIFS(거래!$B$4:$B$191,$A24,거래!$K$4:$K$191,"해당 없음") | G24: =SUM(B24:F24)
A25: Kakao | B25: =COUNTIFS(거래!$B$4:$B$191,$A25,거래!$K$4:$K$191,"있음") | C25: =COUNTIFS(거래!$B$4:$B$191,$A25,거래!$K$4:$K$191,"없음 (확인)") | D25: =COUNTIFS(거래!$B$4:$B$191,$A25,거래!$K$4:$K$191,"식별 불가") | E25: =COUNTIFS(거래!$B$4:$B$191,$A25,거래!$K$4:$K$191,"미확인") | F25: =COUNTIFS(거래!$B$4:$B$191,$A25,거래!$K$4:$K$191,"해당 없음") | G25: =SUM(B25:F25)
A26: Naver | B26: =COUNTIFS(거래!$B$4:$B$191,$A26,거래!$K$4:$K$191,"있음") | C26: =COUNTIFS(거래!$B$4:$B$191,$A26,거래!$K$4:$K$191,"없음 (확인)") | D26: =COUNTIFS(거래!$B$4:$B$191,$A26,거래!$K$4:$K$191,"식별 불가") | E26: =COUNTIFS(거래!$B$4:$B$191,$A26,거래!$K$4:$K$191,"미확인") | F26: =COUNTIFS(거래!$B$4:$B$191,$A26,거래!$K$4:$K$191,"해당 없음") | G26: =SUM(B26:F26)
A27: 합계 | B27: =SUM(B24:B26) | C27: =SUM(C24:C26) | D27: =SUM(D24:D26) | E27: =SUM(E24:E26) | F27: =SUM(F24:F26) | G27: =SUM(G24:G26)
A29: 기업별 편입 시점 판정
A30: 기업 | B30: 편입 후 | C30: 편입 전 | D30: 지분법 합작 계열 | E30: 합계
A31: CJ ENM | B31: =COUNTIFS(거래!$B$4:$B$191,$A31,거래!$M$4:$M$191,"편입 후") | C31: =COUNTIFS(거래!$B$4:$B$191,$A31,거래!$M$4:$M$191,"편입 전") | D31: =COUNTIFS(거래!$B$4:$B$191,$A31,거래!$M$4:$M$191,"지분법 합작 계열") | E31: =SUM(B31:D31)
A32: Kakao | B32: =COUNTIFS(거래!$B$4:$B$191,$A32,거래!$M$4:$M$191,"편입 후") | C32: =COUNTIFS(거래!$B$4:$B$191,$A32,거래!$M$4:$M$191,"편입 전") | D32: =COUNTIFS(거래!$B$4:$B$191,$A32,거래!$M$4:$M$191,"지분법 합작 계열") | E32: =SUM(B32:D32)
A33: Naver | B33: =COUNTIFS(거래!$B$4:$B$191,$A33,거래!$M$4:$M$191,"편입 후") | C33: =COUNTIFS(거래!$B$4:$B$191,$A33,거래!$M$4:$M$191,"편입 전") | D33: =COUNTIFS(거래!$B$4:$B$191,$A33,거래!$M$4:$M$191,"지분법 합작 계열") | E33: =SUM(B33:D33)
A34: 합계 | B34: =SUM(B31:B33) | C34: =SUM(C31:C33) | D34: =SUM(D31:D33) | E34: =SUM(E31:E33)
A36: 기업별 금액 대조
A37: 기업 | B37: 일치 | C37: 불일치 | D37: 기타 | E37: 합계
A38: CJ ENM | B38: =COUNTIFS(거래!$B$4:$B$191,$A38,거래!$L$4:$L$191,"일치") | C38: =COUNTIFS(거래!$B$4:$B$191,$A38,거래!$L$4:$L$191,"불일치") | D38: =COUNTIFS(거래!$B$4:$B$191,$A38,거래!$L$4:$L$191,"기타") | E38: =SUM(B38:D38)
A39: Kakao | B39: =COUNTIFS(거래!$B$4:$B$191,$A39,거래!$L$4:$L$191,"일치") | C39: =COUNTIFS(거래!$B$4:$B$191,$A39,거래!$L$4:$L$191,"불일치") | D39: =COUNTIFS(거래!$B$4:$B$191,$A39,거래!$L$4:$L$191,"기타") | E39: =SUM(B39:D39)
A40: Naver | B40: =COUNTIFS(거래!$B$4:$B$191,$A40,거래!$L$4:$L$191,"일치") | C40: =COUNTIFS(거래!$B$4:$B$191,$A40,거래!$L$4:$L$191,"불일치") | D40: =COUNTIFS(거래!$B$4:$B$191,$A40,거래!$L$4:$L$191,"기타") | E40: =SUM(B40:D40)
A41: 합계 | B41: =SUM(B38:B40) | C41: =SUM(C38:C40) | D41: =SUM(D38:D40) | E41: =SUM(E38:E40)
A43: 그룹이 산 거래(확인 분류 MA①②③)의 손상
A44: 기업 | B44: 거래 | C44: 있음 | D44: 없음 (확인) | E44: 식별 불가 | F44: 미확인 | G44: 해당 없음 | H44: 손상 비율 (있음 ÷ (있음+없음))
A45: CJ ENM | B45: =COUNTIFS(거래!$B$4:$B$191,$A45,거래!$I$4:$I$191,"MA①")+COUNTIFS(거래!$B$4:$B$191,$A45,거래!$I$4:$I$191,"MA②")+COUNTIFS(거래!$B$4:$B$191,$A45,거래!$I$4:$I$191,"MA③") | C45: =COUNTIFS(거래!$B$4:$B$191,$A45,거래!$I$4:$I$191,"MA①",거래!$K$4:$K$191,"있음")+COUNTIFS(거래!$B$4:$B$191,$A45,거래!$I$4:$I$191,"MA②",거래!$K$4:$K$191,"있음")+COUNTIFS(거래!$B$4:$B$191,$A45,거래!$I$4:$I$191,"MA③",거래!$K$4:$K$191,"있음") | D45: =COUNTIFS(거래!$B$4:$B$191,$A45,거래!$I$4:$I$191,"MA①",거래!$K$4:$K$191,"없음 (확인)")+COUNTIFS(거래!$B$4:$B$191,$A45,거래!$I$4:$I$191,"MA②",거래!$K$4:$K$191,"없음 (확인)")+COUNTIFS(거래!$B$4:$B$191,$A45,거래!$I$4:$I$191,"MA③",거래!$K$4:$K$191,"없음 (확인)") | E45: =COUNTIFS(거래!$B$4:$B$191,$A45,거래!$I$4:$I$191,"MA①",거래!$K$4:$K$191,"식별 불가")+COUNTIFS(거래!$B$4:$B$191,$A45,거래!$I$4:$I$191,"MA②",거래!$K$4:$K$191,"식별 불가")+COUNTIFS(거래!$B$4:$B$191,$A45,거래!$I$4:$I$191,"MA③",거래!$K$4:$K$191,"식별 불가") | F45: =COUNTIFS(거래!$B$4:$B$191,$A45,거래!$I$4:$I$191,"MA①",거래!$K$4:$K$191,"미확인")+COUNTIFS(거래!$B$4:$B$191,$A45,거래!$I$4:$I$191,"MA②",거래!$K$4:$K$191,"미확인")+COUNTIFS(거래!$B$4:$B$191,$A45,거래!$I$4:$I$191,"MA③",거래!$K$4:$K$191,"미확인") | G45: =COUNTIFS(거래!$B$4:$B$191,$A45,거래!$I$4:$I$191,"MA①",거래!$K$4:$K$191,"해당 없음")+COUNTIFS(거래!$B$4:$B$191,$A45,거래!$I$4:$I$191,"MA②",거래!$K$4:$K$191,"해당 없음")+COUNTIFS(거래!$B$4:$B$191,$A45,거래!$I$4:$I$191,"MA③",거래!$K$4:$K$191,"해당 없음") | H45: =IF(C45+D45=0,0,C45/(C45+D45))
A46: Kakao | B46: =COUNTIFS(거래!$B$4:$B$191,$A46,거래!$I$4:$I$191,"MA①")+COUNTIFS(거래!$B$4:$B$191,$A46,거래!$I$4:$I$191,"MA②")+COUNTIFS(거래!$B$4:$B$191,$A46,거래!$I$4:$I$191,"MA③") | C46: =COUNTIFS(거래!$B$4:$B$191,$A46,거래!$I$4:$I$191,"MA①",거래!$K$4:$K$191,"있음")+COUNTIFS(거래!$B$4:$B$191,$A46,거래!$I$4:$I$191,"MA②",거래!$K$4:$K$191,"있음")+COUNTIFS(거래!$B$4:$B$191,$A46,거래!$I$4:$I$191,"MA③",거래!$K$4:$K$191,"있음") | D46: =COUNTIFS(거래!$B$4:$B$191,$A46,거래!$I$4:$I$191,"MA①",거래!$K$4:$K$191,"없음 (확인)")+COUNTIFS(거래!$B$4:$B$191,$A46,거래!$I$4:$I$191,"MA②",거래!$K$4:$K$191,"없음 (확인)")+COUNTIFS(거래!$B$4:$B$191,$A46,거래!$I$4:$I$191,"MA③",거래!$K$4:$K$191,"없음 (확인)") | E46: =COUNTIFS(거래!$B$4:$B$191,$A46,거래!$I$4:$I$191,"MA①",거래!$K$4:$K$191,"식별 불가")+COUNTIFS(거래!$B$4:$B$191,$A46,거래!$I$4:$I$191,"MA②",거래!$K$4:$K$191,"식별 불가")+COUNTIFS(거래!$B$4:$B$191,$A46,거래!$I$4:$I$191,"MA③",거래!$K$4:$K$191,"식별 불가") | F46: =COUNTIFS(거래!$B$4:$B$191,$A46,거래!$I$4:$I$191,"MA①",거래!$K$4:$K$191,"미확인")+COUNTIFS(거래!$B$4:$B$191,$A46,거래!$I$4:$I$191,"MA②",거래!$K$4:$K$191,"미확인")+COUNTIFS(거래!$B$4:$B$191,$A46,거래!$I$4:$I$191,"MA③",거래!$K$4:$K$191,"미확인") | G46: =COUNTIFS(거래!$B$4:$B$191,$A46,거래!$I$4:$I$191,"MA①",거래!$K$4:$K$191,"해당 없음")+COUNTIFS(거래!$B$4:$B$191,$A46,거래!$I$4:$I$191,"MA②",거래!$K$4:$K$191,"해당 없음")+COUNTIFS(거래!$B$4:$B$191,$A46,거래!$I$4:$I$191,"MA③",거래!$K$4:$K$191,"해당 없음") | H46: =IF(C46+D46=0,0,C46/(C46+D46))
...

Sheet 거래
A1: 식별 | H1: 분류 요약 | N1: 원자료 (Capital IQ) | S1: v4 분야 (수집에서 확인 안 함) | U1: 10-19 설명란 판정 | Z1: 공시 확인 | AH1: 인수 목적·핵심 | AM1: 규모 | AS1: 주가 이벤트 | AV1: 전후 이벤트 | AZ1: 성과 | BF1: 수집
A2: 거래 | B2: 기업 | C2: 날짜 | D2: 대상회사 | E2: 금액 순위 | F2: 상위 50 | G2: 사건 묶음 | H2: 거래 형태 (설명란 판정) | I2: 거래 형태 (공시 확인) | J2: 형태 변경 | K2: 손상 구분 | L2: 금액 대조 | M2: 편입 시점 | N2: 상태 | O2: 금액 $M | P2: 매수자 | Q2: 매도자 | R2: 설명란 | S2: 분야 | T2: 세부 분야 | U2: 그룹 역할 (설명란 판정) | V2: 지분 규모 (설명란 판정) | W2: 거래 형태 (설명란 판정) | X2: 편입 전 표시 (배경지식) | Y2: 금액 의심 (설명란 대조) | Z2: 거래 형태 (공시 확인) | AA2: 편입 시점 (공시 확인) | AB2: 상태 (공시 확인) | AC2: 금액 확인 (현지 통화) | AD2: 금액 확인 ($M) | AE2: 발표일 | AF2: 확인 메모 | AG2: 특이사항 | AH2: 인수 주체 | AI2: 발표 당시 목적 | AJ2: 인수 주체 주력 사업 | AK2: 핵심 여부 | AL2: 핵심 판정 근거 | AM2: 인수 주체 총자산 | AN2: 그룹 정점 총자산 | AO2: 총자산 대비 | AP2: 자기자본 대비 | AQ2: 시가총액 | AR2: 규모 기준 | AS2: 종목 | AT2: 종목 근거 | AU2: 처음 알려진 날 | AV2: 인수 전 사건 | AW2: 인수 후 사건 | AX2: 손상 | AY2: 손상 구분 근거 | AZ2: 매출 (인수 전) | BA2: 매출 (인수 후) | BB2: 영업이익 (인수 전) | BC2: 영업이익 (인수 후) | BD2: 실적 기준 | BE2: 어닝콜·IR 언급 | BF2: 수집 상태 | BG2: 수집 일시
A3: deal_id | B3: firm | C3: date | D3: target | E3: value_rank | F3: top50 | G3: event_group | H3: (파생) | I3: (파생) | J3: (파생) | K3: impairment_class | L3: (파생) | M3: (파생) | N3: status | O3: value | P3: buyers | Q3: sellers | R3: comment | S3: cat | T3: subcat | U3: role | V3: stake | W3: subtype | X3: pre_incorp | Y3: value_flag | Z3: subtype_chk | AA3: pre_incorp_chk | AB3: status_chk | AC3: value_chk_local | AD3: value_chk_usdmm | AE3: announce_date_chk | AF3: chk_note | AG3: notes | AH3: acquirer_entity | AI3: purpose_quote | AJ3: acquirer_core | AK3: is_core | AL3: core_basis | AM3: acq_total_assets | AN3: apex_total_assets | AO3: deal_to_assets_pct | AP3: deal_to_equity_pct | AQ3: acq_mktcap | AR3: size_basis | AS3: event_ticker | AT3: event_ticker_basis | AU3: first_filing_date | AV3: pre_events_summary | AW3: post_events_summary | AX3: impairment | AY3: impairment_class_basis | AZ3: target_rev_pre | BA3: target_rev_post | BB3: target_op_pre | BC3: target_op_post | BD3: perf_basis | BE3: earnings_call_note | BF3: collect_status | BG3: collected_on
A4: C001 | B4: CJ ENM | C4: 2006-01-09 | D4: CJ Entertainment Inc. | E4: 10 | F4: True | H4: MA② | I4: MA② | J4: 같음 | K4: 해당 없음 | L4: 불일치 | M4: 편입 전 | N4: Closed | O4: 549.08 | P4: CJ Corporation (KOSE:A001040) | Q4: - | R4: CJ Corp. (KOSE: A001040) agreed to acquire the remaining stake in CJ Entertainment Inc. for KRW 264 billion in stocks on January 9, 2006. As per the terms of the agreement, CJ Corp. will pay 17.8 shares of its common stock to every 100 shares of CJ Entertainment. The Board of CJ Corp approved the transaction. The acquisition is subject top approval of shareholders of CJ Corp. A shareholder meeting is scheduled on March 7, 2006 and the transaction is expected to complete on April 10, 2006. | S4: Content Production & Investment | T4: Content Investment / Distribution | U4: MA-1 그룹이 매수자 | V4: 기존 자회사 잔여지분 | W4: MA② 기존 지분 확대 | Y4: False | Z4: MA② 기존 지분 확대 | AA4: 편입 전 (매수자는 CJ ENM 계보 밖: CJ㈜(CJ그룹 지배회사, 당시 식품·제약 사업지주, 2007-11 순수지주회사 전환)). 참고: 대상 구 CJ엔터테인먼트는 이 거래에서 영화사업을 물적분할(신설 씨제이엔터테인먼트㈜, CJ㈜ 100%)한 뒤 존속 투자법인 CJ EH㈜가 CJ㈜에 흡수돼 소멸했고, 영화사업 법인은 2011-03-01 오미디어홀딩스(CJ E&M)에 합병(C005)된 뒤 2018-07-01 CJ오쇼핑의 CJ E&M 흡수합병으로 현 CJ ENM 법인에 들어옴 | AB4: 완료 (2006-04-10 합병기일·분할기일; 2006-04-17 해산등기, 2006-04-20 구 CJ엔터테인먼트 코스닥 상장폐지, 2006-04-25 CJ㈜ 합병신주 상장 예정) | AC4: 397,237,024,295원 (합병신주 3,176,905주 × CJ㈜ 합병가액 125,039원; 피합병 CJ EH(구 CJ엔터테인먼트) 발행주식 17,827,713주 × 0.1782004). 이 중 CJ㈜ 보유 6,556,101주(36.77%)에 배정된 약 1,168,300주는 CJ㈜ 자기주식이 됨(합병신고서). 나머지 지분 중 14.85%(2,647,042주)는 CJ그룹 회장 이재현, 0.13%(23,040주)는 대표이사 박동호 몫이라 CJ㈜·특수관계인 합계 9,226,183주(51.76%). 특수관계인 밖 외부주주(8,601,530주, 48.24%)의 실질 대가 = 주식매수청구 현금 67,416,510,174원(3,123,159주 × 21,586원) + 잔여 외부주주 5,478,371주에 교부된 신주 976,247주(합병가액 기준 122,068,948,633원) = 189,485,458,807원(계산). 참고: 이재현 몫 신주 471,703주(58,981,271,417원) | AD4: 원자료와 불일치: 합병신주 전체 397,237백만원 = 409.2백만 달러, 특수관계인 밖 외부주주 실질 대가 189,485백만원 = 195.2백만 달러 (Yahoo Finance KRW=X 2006-01-09 종가 970.72원/달러 적용, 계산). 원자료 549.08은 같은 환율로 약 5,330억원으로, 합병신주 가치·발표 직전 CJ㈜ 종가(136,000원) 기준 신주 가치 4,321억원·여기에 CJ엔터 부채(2005-09-30 841억원 또는 2005-12-31 1,523억원)를 더한 값·CJ엔터 100% 시가 4,154억원 중 어느 것으로도 재현되지 않음 | AE4: 2006-01-09 | AF4: 기준 분류 유지(MA②): CJ㈜는 거래 전 CJ엔터테인먼트 지분 36.77%를 가진 지배회사(합병결정 공시 '회사와의 관계: 지배회사', CJ㈜ 2006 감사보고서 '자회사')였고 특수관계인(이재현 14.85%, 박동호 0.13%) 포함 51.76%를 지배했으며, 이 거래로 영화사업 법인(신설 CJ엔터테인먼트)을 100% 자회사로 만들고 나머지 소수주주를 흡수함. 원자료 설명란 정정: (1) 거래 형식은 '주식교환'이 아니라 CJ엔터테인먼트를 물적분할(영화사업→신설 씨제이엔터테인먼트㈜)한 뒤 존속 투자사업법인 CJ EH㈜를 CJ㈜가 흡수합병한 구조(회사분할결정·회사합병결정). (2) 'KRW 264 billion'은 합병결정 공시에 적힌 CJ엔터테인먼트의 2005년 3분기 자산총계 264,025백만원과 같은 숫자로 거래대금이 아님(외부 지분을 발표 직전 종가 23,300원으로 평가한 2,626억원과도 비슷하나 공시된 대가는 아님). 공시 기준 대가는 합병신주 전체 3,972억원, 특수관계인 밖 외부주주 실질 대가 1,895억원. (3) '17.8 shares per 100 shares'(0.1782004), 주총 2006-03-07, 완료 2006-04-10은 공시와 일치. 원자료 sellers '-'는 CJ엔터테인먼트 소수주주(이재현 등 특수관계인 14.98%와 외부주주 48.24%, 주식매수청구 3,123,159주 포함). 분류 해석 주의: 매수자 CJ㈜를 '그룹'으로 본 원자료 기준을 따름 — 최신 CJ 계보 규칙처럼 그룹을 CJ ENM 계보로 좁히면 CJ㈜는 계보 밖이라 구조상 MA⑥으로도 볼 수 있음(사용자 확인 필요) | AG4: C005의 선행 거래: 이 합병으로 신설된 씨제이엔터테인먼트㈜(DART 00576309, 2006-04-10 설립, CJ㈜ 100%)가 2010-11-16 결정된 6사 합병(C005)에서 CJ E&M에 흡수됨. 구 CJ엔터테인먼트(DART 00330406, 코스닥 A049370)는 1997-07-28 설립 투자자문회사로 2000-04-18 CJ㈜ 엔터테인먼트 사업부를 현물출자받아 영화사업을 시작했고 2002-02-05 코스닥에 등록됨(CJ㈜ 2006 감사보고서 주석 22). 합병 전 구 CJ엔터테인먼트는 CJ CGV 36.73%, CJ미디어 31.16%, CJ인터넷 9.53%, 시네마서비스 40.00%, 아트서비스 59.72%, CJ엔키노 86.13% 등을 가진 미디어 중간지주였고(합병신고서 출자내역, 2005-09-30), 이 거래로 CJ㈜가 이 지분을 직접 보유하게 됨 — 공시된 합병목적 자체가 'CJ미디어·CJ CGV·CJ인터넷의 직접 지배'임. 주주 구성(2006-01-06): CJ㈜ 36.78%, 이재현 14.85%, 박동호 0.13%(특수관계 계 51.76%), 랜드마크자산운용 5.00%; 이재현은 합병으로 CJ㈜ 신주 471,703주를 받음(합병종료보고서 지분변동표). CJ㈜도 반대주주 주식매수청구 732,736주(보통주 청구가 114,298원)를 받음. 회계처리: 지배·종속회사 간 합병이라 CJ EH의 자산·부채를 연결재무제표상 장부가액으로 승계하고 차액은 자본잉여금 처리(CJ㈜ 2006 감사보고서 주석 22) → 이 거래로 새 영업권은 생기지 않음. 같은 날(2006-01-09) CJ㈜는 CJ모닝웰 소규모합병도 결정함(별개 거래, 신주 683,299주). 공시 시점: CJ엔터 매매거래정지가 2006-01-09 17:11:07에 시작돼(정규장 마감 후) 2006-01-10까지 연장됨(20060109900089). 조사 한계: 2006년 DART 문서 일부(구 CJ엔터 사업보고서 연혁·타법인출자 절)는 서버가 깨진 글자로 돌려줘 읽지 못함. 2006년 당시 언론 보도·IR 자료는 찾지 못함(수집 2회·검토 3회 웹 검색). 영화사업 법인이 2006-04 신설돼 2006년 실적은 9개월치이고, 구 CJ엔터 실적에는 지분법손익 등 투자사업이 섞여 있어 전후 비교에 주의. collect_status 부분: earnings_call_note 미확인 | AH4: CJ㈜ (CJ주식회사, 당시 식품·사료·제약을 직접 영위하던 CJ그룹 지배회사, 유가증권시장 001040; 2007-09 CJ제일제당 인적분할로 순수지주회사 전환) | AI4: "CJ엔터테인먼트㈜가 지배하고 있는 CJ 미디어, CJ CGV, CJ 인터넷은 신성장사업으로 지속적 투자가 요구되는 바, CJ㈜가 직접 지배함으로써 지속 성장시키기 위함" (회사합병결정 공시 합병목적) / "경영 효율성 향상 및 기업 가치 극대화" (합병신고서 합병의 목적) / "투자사업부문과 영화사업부문으로 분리하여 업종 전문화를 통해 ... 전문화된 사업영역에 기업의 역량을 집중" (CJ엔터테인먼트 회사분할결정 분할목적) | AJ4: 식품·사료·제약 제조업(합병결정 공시상 주요사업 '당분유제조'); 2005년 별도 매출 2,459,901백만원·영업이익 192,480백만원(CJ㈜ 2005 사업보고서). 미디어·엔터 사업은 직접 영위하지 않고 지분법 자회사로 보유(2005-09-30 CJ엔터테인먼트 36.78%, CJ미디어 58.06%, CJ인터넷 16.23%, CJ뮤직 95.51%, CJ홈쇼핑 29.99%; 합병신고서 출자내역) | AK4: 비핵심 | AL4: 인수 주체 CJ㈜의 직접 사업은 식품·제약이고 영화·미디어는 자회사로만 보유했으므로 CJ㈜ 기준으로는 비핵심 영역의 자회사 지분 확대. 다만 CJ그룹은 2000년부터 CJ엔터테인먼트를 통해 영화사업을 해 왔고, 그룹 정점 CJ ENM 기준으로 보면 영화사업은 현 CJ ENM 영화드라마 부문의 전신이라 핵심 영역 | AM4: 2,790,157백만원 (CJ㈜ 별도, 2005-12-31; CJ㈜ 2005 사업보고서 요약재무정보, CJ㈜ 2006 감사보고서 주석 22의 2005-12-31 요약대차대조표도 같은 값). 참고: CJ엔터테인먼트가 낸 합병결정 공시의 CJ㈜ 2005-09-30 자산총계 2,759,575백만원, 합병종료보고서 '합병전'(CJ모닝웰 합병 반영 후) 2,820,644,848천원 | AN4: acq_total_assets와 같음 (인수 주체 CJ㈜가 상장 지배회사 자신). 연결 기준 CJ㈜ 및 종속회사 총자산 5,990,100,383천원 (2005-12-31, CJ㈜ 연결감사보고서; 2006년 연결감사보고서의 비교표시는 5,997,710,235천원). 참고: 2004-12-31 연결 5,197,979,683천원 | AO4: 계산: 14.24 (합병신주 전체 397,237백만원 ÷ CJ㈜ 별도 총자산 2,790,157백만원, 2005-12-31). 특수관계인 밖 외부주주 실질 대가 기준 6.79 (189,485백만원 ÷ 같은 분모). 연결 총자산(5,990,100백만원) 대비 6.63. 합병 공시에 총자산대비 항목 없음 | AP4: 계산: 26.91 (397,237백만원 ÷ CJ㈜ 별도 자본총계 1,476,097백만원, 2005-12-31). 특수관계인 밖 외부주주 실질 대가 기준 12.84 | AQ4: 계산: 3,271,374,872,000원 (보통주만: 2006-01-06 종가 136,000원 × 보통주 24,054,227주; 종가는 합병신고서 합병가액 표, 주식수는 같은 신고서의 2006-01-06 기준 발행주식수). 우선주 6,051,488주(1우 3,587,656·2우 1,617,526·3우 846,306주)는 당시 종가를 확인하지 못해 제외. 참고: 공시가 2006-01-09 정규장 마감 후라 발표 직전 거래일을 2006-01-09로 보면 추정: 종가 약 133,500원(Yahoo Finance 001040.KS 수정종가 21,192.42 × 136,000/21,586.34) × 24,054,227주 ≈ 3,211,239,304,500원 | AR4: 총자산·자본은 CJ㈜ 2005-12-31 별도 값(2005 사업보고서 20060331000758 요약재무, 2006 감사보고서 20070309000171 주석 22), 연결 총자산은 2005 연결감사보고서(20060501000035). 거래금액은 합병신고서(20060109000341)의 합병가액 125,039원·22,282원과 합병종료보고서(20060419000229)의 신주 3,176,905주, 주식매수청구 3,123,159주×21,586원, 합병신고서 주식분포(특수관계인 9,226,183주)로 계산. 시가총액은 2006-01-06 종가 기준(2006-01-09 종가 추정치 병기). Yahoo Finance 001040.KS 종가는 이후 분할 등을 반영한 수정값(2006-01-06 21,586원)이라 직접 쓰지 않고 비율로만 씀 | AS4: KRX:001040 | AT4: 인수 주체 CJ㈜(유가증권시장). 공시는 2006-01-09 정규장 마감 후(CJ엔터 매매정지 17:11:07)라 CJ㈜의 첫 반응일은 2006-01-10. 대상 구 CJ엔터테인먼트도 코스닥 상장사(KRX:049370, 2002-02-05 상장, 2006-04-20 피흡수합병으로 상장폐지): 발표 직전 2006-01-06 종가 23,300원, 시가총액 계산 415,385,712,900원(17,827,713주 기준); 주권 매매거래정지 2006-01-09 17:11:07~2006-01-10(20060109900082, 정지기간변경 20060109900089)이라 대상 주식의 첫 반응일은 2006-01-11. 049370은 상장폐지 종목이라 Yahoo Finance에 시세 없음 | AU4: 2006-01-09 정규장 마감 후: DART에 CJ㈜ 회사합병결정(20060109000243)·합병신고서, CJ엔터테인먼트 회사분할결정(20060109000249)·회사합병결정이 같은 날 공시되고 CJ엔터테인먼트 주권 매매거래정지(17:11:07부터, 2006-01-10까지 연장). 2005-09~2006-01 CJ엔터 공시 목록에 관련 조회공시 없음, 사전 보도는 찾지 못함 | AV4: 1997-07: 법인 설립(투자자문·경영자문업); 2000-04: CJ㈜ 엔터테인먼트 사업부 현물출자로 영화사업 개시; 2002-02: 코스닥 등록; 2005-09: CJ㈜가 36.78% 보유, CJ엔터는 CJ CGV 36.73%·CJ미디어 31.16%·CJ인터넷 9.53% 등 보유한 미디어 중간지주; 2004→2005: 별도 매출 118,986→124,364백만원, 영업손실 2,576→3,942백만원(일부 투자작품 손실·인건비 증가; 2004년 경상이익 26,058백만원은 지분법주식 처분이익 영향) | AW4: 2006-03-07: 양사 임시주총 분할·합병 승인, CJ엔터테인먼트는 CJ EH㈜로 상호 변경; 2006-04-10: 영화사업 물적분할(신설 씨제이엔터테인먼트㈜, CJ㈜ 100%)과 CJ EH㈜ 흡수합병 동시 완료, 주식매수청구 3,123,159주(21,586원); 2006-04-20: 구 CJ엔터 상장폐지; 2006-12: <타짜> 685만 관객; 2007-09: CJ㈜ 인적분할(CJ제일제당 신설)로 지주회사 전환; 2009-08: <해운대> 1,152만 관객; 2010-11-16: 신설 CJ엔터테인먼트 등 5사를 오미디어홀딩스가 흡수합병 결정(C005); 2011-03-01: CJ E&M 영화사업부문으로 편입; 2016·2017: CJ E&M 영화부문 영업손실(-23,874·-9,044백만원); 2018-07-01: CJ오쇼핑이 CJ E&M 흡수합병, CJ ENM 출범; 2024: CJ ENM 영화드라마사업부문 매출 1,704,683백만원·영업손실 26,925백만원(스튜디오드래곤·Fifth Season 포함) | AX4: 해당 없음 (이 합병으로 영업권이 생기지 않음: CJ㈜ 2006 감사보고서 주석 22에 지배·종속회사 간 합병으로 연결재무제표상 장부가액 승계, 차액은 자본잉여금 처리라고 기재. CJ㈜ 2006 무형자산 주석의 '합병으로 인한 증가' 영업권 13,826백만원은 같은 해 4개사 합병 합계로 CJ EH 몫은 구분 공시되지 않음). 후속 사업 수준 참고: CJ E&M 2015년 판권 손상차손 95,154백만원(방송·영화 판권 전체, CJ E&M 2015 사업보고서 주석 15) | AY4: 지배·종속회사 간 합병으로 영업권이 생기지 않음(CJ㈜ 2006 감사보고서) | AZ4: 2004: 118,986백만원; 2005: 124,364백만원 (구 CJ엔터테인먼트 별도) | BA4: 2006(2006-04-10~12-31, 신설 CJ엔터테인먼트 제1기): 118,381백만원; 2007: 129,857백만원; 최근(독립 법인 마지막 연도) 2010: 163,080,002,913원. 후속 사업 대리지표 — CJ E&M 영화부문(연결): 2011 166,784백만원(합병 후 3~12월), 2012 218,960백만원, 2017 198,667백만원; CJ ENM 영화드라마사업부문 2024 1,704,683백만원(드라마 제작사 포함으로 비교 불가) | BB4: 2004: -2,576백만원; 2005: -3,942백만원 (구 CJ엔터테인먼트 별도; 감사 완료 정정공시 2006-03-09 기준 2004 -2,576,063,521원·2005 -3,942,273,146원. 2006-01-26 최초 잠정공시는 감사 전 수치로 2004 1,045,124,599원·2005 -4,180,994,921원이었음) | BC4: 2006(9개월): -14,148백만원; 2007: -17,149백만원; 최근(독립 법인 마지막 연도) 2010: 8,329,368,008원. CJ E&M 영화부문: 2011 5,834백만원, 2012 9,220백만원, 2017 -9,044백만원; CJ ENM 영화드라마 2024 -26,924,539천원 | BD4: 인수 전: 구 CJ엔터테인먼트(CJ EH) 별도·K-GAAP·12월 결산, 2005 사업보고서(20060331002319) 요약재무정보와 감사 완료 정정공시(20060309001167; 2005 매출 124,363,747,563원·영업손실 3,942,273,146원, 2004 매출 118,985,835,542원·영업손실 2,576,063,521원), CJ㈜ 2006 감사보고서 주석 22(2005년 매출 124,364·영업손실 3,942백만원 일치). 구 법인 실적에는 영화사업 외에 지분법 등 투자사업 손익이 섞임. 인수 후: 2006-04-10 물적분할로 신설된 씨제이엔터테인먼트㈜(영화사업 법인) 별도·K-GAAP — 2006~2009는 2010 증권신고서(합병, 20101202000223) 요약재무, 2010은 감사보고서(20110331003203). 2011-03 이후는 CJ E&M 연결 영화부문(K-IFRS, 사업보고서 '사업부문별 요약 연결재무현황')과 CJ ENM 영화드라마사업부문(2024 사업보고서 영업부문 주석)으로 대신함 — 범위가 계속 바뀌어 시계열 비교에 주의 | BE4: 미확인 — 2006년 CJ㈜ IR 자료·실적발표와 어닝콜 기록을 찾지 못함(DART에는 IR 자료 없음; 수집 2회·검토 3회(한국어 2·영어 1) 웹 검색). 참고: 2010-11-16 CJ그룹 발표(이투데이 보도)는 신설 CJ엔터테인먼트를 포함한 6사 통합 목적을 '콘텐츠 사업의 글로벌화와 계열사간 시너지 극대화'로 밝힘(C005 참조) | BF4: 부분 | BG4: 2026-10-26
A5: C002 | B5: CJ ENM | C5: 2006-10-12 | D5: Orion Cinema Network Co., Ltd. | E5: 70 | F5: False | H5: MA② | I5: MA② | J5: 같음 | K5: 식별 불가 | L5: 불일치 | M5: 편입 후 | N5: Closed | O5: 20.89 | P5: On Media Corp. | Q5: - | R5: On Media Corp. (KOSE:A045710) acquired an additional stake in Orion Cinema Network Co., Ltd. for KRW 20 billion in cash on October 12, 2006. | S5: Media Platforms | T5: Broadcasting Channel | U5: MA-1 그룹이 매수자 | V5: 추가지분 | W5: MA② 기존 지분 확대 | Y5: False | Z5: MA② 기존 지분 확대 | AA5: 편입 후 (CJ ENM 전신 계보: 온미디어, 2011 CJ ENM 계보로 합병 — 2011-03-01 CJ E&M(옛 오미디어홀딩스)에 흡수합병, CJ E&M은 2018-07-01 CJ오쇼핑(현 CJ ENM 법인)에 흡수합병). 참고(시점 사실): 거래 당시(2006-10) 온미디어는 ㈜오리온이 최대주주인 오리온그룹 계열 상장사로 CJ와 자본관계가 없었고, CJ오쇼핑의 온미디어 경영권 취득은 2010-06-08(오리온 측 40.18% 대금지급, C004)임 | AB5: 완료 (2006-11-14 주금 납입; 이사회 결의 2006-10-12, 실권주 인수로 취득 규모 확대 정정 2006-11-14) | AC5: 23,957,220,000원 (오리온시네마네트워크 주주배정 유상증자 신주 4,791,444주 × 발행가 5,000원(액면가) 전량 인수; 최초 공시는 배정분 4,000,000주·20,000,000,000원이었으나 2대주주 ㈜중앙일보사 배정분 791,444주가 실권돼 온미디어가 인수 — 2006-11-14 정정공시) | AD5: 원자료와 불일치(최종 금액 기준): 23,957백만원 = 25.58백만 달러 (계산: Fed H.10 2006-11-14 936.70원/달러; 2006-10-12 957.60원 적용 시 25.02). 원자료 20.89는 최초 공시액 200억원 ÷ 957.60원(2006-10-12) = 20.89로 재현됨 — 실권주 인수분이 빠진 값 | AE5: 2006-10-12 | AF5: 기준 분류 유지(MA② 기존 지분 확대): 온미디어는 거래 전 OCN 5,740,000주(83.48%)를 가진 지배주주였고 이 거래로 90.27%(10,531,444주/11,667,165주)가 됨. 다만 매도자에게서 산 거래가 아니라 자회사 주주배정 유상증자 참여(신주 인수)이며 대가는 OCN으로 들어가 단기차입금 상환에 쓰임(OCN 2006 감사보고서). 금액 정정: 원자료 'KRW 20 billion'은 최초 결의액이고 확정 취득액은 23,957,220,000원(4,791,444주). 원자료 sellers '-'는 구조상 맞음(신주 발행). 분류·상태는 원자료와 일치 | AG5: 온미디어 계보 묶음(CJ-B)의 첫 거래로 CJ 편입 4년 전 오리온그룹 시절 거래. 대상 OCN(㈜오리온시네마네트워크)은 2013-12-01 CJ E&M에 흡수합병(C012 — 잔여 9.73%를 가진 ㈜중앙일보사 몫을 합병신주로 정리)되므로 C002→C012가 OCN 지분 100% 정리의 앞뒤 단계. 9.73%는 바로 이 증자에서 중앙일보가 실권해 16.52%→9.73%로 낮아진 지분임. 공시상 '발행회사의 요약 재무상황'(자산 298,356·매출 59,801백만원 등)은 OCN이 아니라 온미디어 자신의 2005 재무로 보임(OCN 2005 자산총계는 99,306,934,951원) — 공시 표 오기 가능성. 증자 목적은 공시상 '운영자금'이며 OCN은 증자 대금으로 단기차입금(2005말 11,515,684천원)을 전액 상환함. 같은 달(2006-10-27) 온미디어는 온라인게임사 이플레이온을 200억원에 100% 출자 설립(별건, 2010-10 청산 결정). 시가총액은 발표 직전 거래일 종가를 찾지 못해 월간 범위로 추정함(KRX 일별 시세 접근 불가, Yahoo Finance에 상장폐지 종목 045710 시세 없음). 이후 실적은 2013-12 합병 전까지 OCN 별도 감사보고서로, 합병 뒤에는 개별 실적이 공시되지 않아 CJ E&M 방송부문·CJ ENM 미디어플랫폼 부문으로만 대리 추적 가능 | AH5: ㈜온미디어 (ON*Media Corp., 유가증권시장 045710 — 2006-07-03 상장; 당시 ㈜오리온이 최대주주(44,152,210주, 발행주식 115,797,990주 대비 38.13% 계산)인 오리온그룹 계열 방송채널사용사업 겸 사업지주회사. 2010-06 CJ오쇼핑에 인수, 2011-03-01 CJ E&M에 흡수합병돼 소멸) | AI5: "자회사의 운영자금 조달을 위한 유상증자참여" (타법인주식및출자증권취득결정 취득목적) / 자금조달의 목적: 운영자금 23,957,220,000원 (자회사 OCN 유상증자결정, 자회사의 주요경영사항) | AJ5: 방송채널사용사업(MPP)을 영위하는 사업지주회사. 2005 별도 영업수익 59,776백만원 = 지분법평가이익 19,940 + 자회사 수수료수익 14,433 + 직영 채널(투니버스) 광고 16,304·시청료 5,287·사업수익 3,812(2006 사업보고서 매출실적, 백만원). 자회사 OCN·바둑TV·온게임넷(PP), 4개 SO, 디지틀온미디어 보유. 2005 MPP 매출 점유율 12.2%(16개 채널, 방송위원회 자료 인용) | AK5: 핵심 | AL5: OCN은 영화채널 OCN·Super Action·Catch On·On Style 등 6개 채널을 운영하는 온미디어의 최대 자회사(2005 매출 100,340백만원)로 인수 주체의 주력인 케이블 PP 사업 그 자체. 그룹 정점(현 CJ ENM, 미디어플랫폼 부문의 TV채널 사업) 기준으로도 OCN은 지금도 운영 중인 핵심 채널이라 '핵심' | AM5: 298,355,727,088원 (온미디어 별도, 2005-12-31; 타법인주식취득결정 '최근 사업연도말 자산총액') | AN5: acq_total_assets와 같음 (인수 주체 온미디어가 상장사 자신; 당시 상위 상장 지배회사 ㈜오리온은 CJ ENM 계보 밖). 참고: 온미디어 연결 총자산 379,287백만원(2005-12-31, 2009 사업보고서 요약연결재무정보 제6기) | AO5: 8.03 | AP5: 8.36 | AQ5: 추정: 약 7,295억~9,785억원 (발표 직전 거래일 2006-10-11 종가 미확인. 2006년 10월 월중 최저 6,300원·최고 8,450원(2006 사업보고서 '최근 6개월 간의 주가') × 발행주식 115,797,990주(2006-11-10 신주인수권 행사 350,000주 전; 2006말 116,147,990주 = 자본금 58,074백만원/액면 500원에서 역산). 참고: 2006-09-27 장중 7,310원(이투데이) 기준 8,465억원) | AR5: 총자산·자기자본(286,535,479,074원)·비율은 2006-11-14 정정 타법인주식취득결정(20061114001237) 값(분모 2005-12-31 별도). 최초 공시(20061012000143)는 200억원 기준 총자산대비 6.70%·자기자본대비 6.98%. 시가총액은 일별 종가가 없어 월간 범위로 추정 | AS5: KRX:045710 | AT5: 인수 주체 온미디어(유가증권시장 045710, 2011-03 합병으로 상장폐지 — Yahoo Finance 시세 없음). 대상 OCN은 비상장. 당시 최대주주 ㈜오리온(KRX:001800, 현 오리온홀딩스)도 참고 가능. 공시는 2006-10-12 장중/장후 여부 미확인 | AU5: 2006-10-12: DART 온미디어 '유상증자결정(자회사의 주요경영사항)'·'타법인주식및출자증권취득결정' 동시 공시. 사전 보도나 조회공시는 찾지 못함(온미디어 2006-07~10 공시 목록 확인) | AV5: 1999-05-18: OCN 설립(오리온그룹), 1999년 중 ㈜대우 DCN 채널(매수가 150억원)과 ㈜중앙일보 Catch One 채널(74억원) 사업권 양수(OCN 감사보고서 영업권 주석: 자산·부채 양수, 매수가 DCN 15,000,000천원·Catch One 7,400,000천원). 추정: 중앙일보사가 OCN 지분 16.52%(1,135,721주)를 갖게 된 경위와 관련 있을 수 있으나 주식 취득 경위는 감사보고서에 기재되지 않음; 2000-06-15: 온미디어 설립 시 OCN 지분 50.48% 현물출자로 취득(지주회사); 2004: OCN 매출 75,043백만원·영업이익 12,471백만원; 2005: 매출 100,341백만원·영업이익 24,452백만원, 단기차입금 11,516백만원; 2006-07-03: 온미디어 유가증권시장 상장(공모가 5,200원); 2006-10 초: 외국계 주주(Capital International·Tabimax·New Asia East) 32.69% 보호예수 해제 | AW5: 2006-11-14: 증자 납입, 온미디어 지분 90.27%·중앙일보 9.73%; OCN이 증자 대금으로 단기차입금 전액 상환; 2006: OCN 매출 140,322백만원(+39.8%, '광고시장 성장에 따른 매출액 증가')·영업이익 38,781백만원; 2007~2009: 매출 180,395→170,529→161,261백만원, 영업이익 39,291→21,213→10,005백만원으로 둔화; 2010-06: CJ오쇼핑이 온미디어 55.17% 취득(C004)으로 OCN이 CJ 계열 편입; 2010-09-15: 온미디어 지분이 CJ오쇼핑 인적분할 신설 오미디어홀딩스로 이전; 2011-03-01: 온미디어가 CJ E&M에 흡수합병돼 OCN 지분 90.27%를 CJ E&M이 승계(C009); 2011~2012: OCN 매출 222,297→242,856백만원·영업이익 30,929→33,657백만원; 2013-12-01: CJ E&M이 OCN을 흡수합병(합병비율 1:0.6485944, 중앙일보 9.73%에 CJ E&M 주식 교부, C012) — 법인 소멸, 채널 OCN은 CJ E&M 방송부문으로; 2018-07-01: CJ오쇼핑이 CJ E&M을 흡수합병해 CJ ENM 출범, OCN 채널은 CJ ENM 미디어플랫폼 부문이 운영 | AX5: 확인 안 됨 (온미디어 2009 사업보고서 타법인출자 현황에서 OCN 주식 장부가 162,410→167,120백만원으로 지분법이익만 반영·손상 기재 없음; CJ E&M(오미디어홀딩스) 2010 연결감사보고서 무형자산 변동표 영업권 손상 없음; CJ E&M 2013·2017 연결 무형자산 변동표의 영업권 손상 957백만원·854백만원은 현금창출단위·대상이 특정되지 않음; 2013-12 OCN 합병은 동일지배 합병으로 장부가 승계라 새 영업권 없음. OCN 관련 손상 기재를 찾지 못함) | AY5: 2009~2010 손상 기재 없음, 이후 OCN 관련 영업권이 방송사업부문 현금창출단위에 묶여 개별 손상을 알 수 없음 | AZ5: 2004: 75,042,524,947원; 2005: 100,340,749,421원 | BA5: 2006: 140,321,911,950원; 2007: 180,395,349,700원; 최근 확인 가능 연도 2014: 224,274백만원(CJ E&M 사업보고서 '합병등 전후의 재무사항 비교표' 실적; 2013 242,595백만원, 독립 법인 마지막 감사 연도 2012 242,856,440,260원). 합병 후 대리지표(OCN 외 채널 포함): CJ E&M 방송부문 2014 825,918백만원·2017 1,294,153백만원, CJ ENM 미디어플랫폼 2025 1,341,617백만원(외부매출) | BB5: 2004: 12,471,195,779원; 2005: 24,451,561,884원 | BC5: 2006: 38,780,607,442원; 2007: 39,290,729,401원; 최근 확인 가능 연도 2014: 34,944백만원(비교표 실적, 합병 전 예측 58,767백만원 대비 41% 미달; 2013 23,250백만원·예측 45,918백만원; 2012 감사보고서 33,656,826,184원). 합병 후 대리지표: CJ E&M 방송부문 영업이익 2014 2,150백만원·2017 61,822백만원, CJ ENM 미디어플랫폼 부문 영업이익 2025 1,332,256천원 | BD5: OCN 별도 재무제표, 12월 결산. 2004~2009는 K-GAAP 감사보고서(2005 감사보고서 20060320000290: 2004·2005; 2007 감사보고서 20080408001290: 2006·2007; 2009 감사보고서 20100326000591: 2008·2009 — 2006 이후 손익계산서는 '영업수익·영업비용' 표시), 2010~2012는 K-IFRS 감사보고서(2011 감사보고서 20120328000227, 2012 감사보고서 20130326000223; 2011 영업이익은 2011 감사보고서 30,929백만원, 2012 감사보고서 비교표시 32,032백만원으로 기타영업손익 분류 차이). 2013·2014는 CJ E&M 2014 사업보고서(20150331004213) '합병등 전후의 재무사항 비교표'의 OCN 실적(1차연도 2013·2차연도 2014로 판단 — FY2014 보고서에 두 해 실적이 모두 실림; 합병 후 OCN은 CJ E&M 내부 사업이라 기준·배부 방식 미공시). 2013 1~11월 224,097,517천원은 CJ E&M 2013 연결감사보고서 합병 주석(지배력 획득 시 배분된 인수가격 반영). 합병 후 대리지표는 CJ E&M 사업보고서 '사업부문별 요약 연결재무현황'(2014: 20150331004213, 2017: 20180330004046)과 CJ ENM 2025 사업보고서(20260318001469) 영업부문 주석 — tvN 등 다른 채널·스튜디오드래곤·티빙이 섞여 OCN 단독 성과가 아님 | BE5: 2015-03-31 CJ E&M 2014 사업보고서(합병 사후 비교): OCN 2014 매출 224,274백만원·영업이익 34,944백만원으로 합병 전 예측(293,483·58,767) 대비 24%·41% 미달, 사유 "방송 광고시장의 업황 부진"·"킬러 콘텐츠 확보 및 제작역량 강화를 위해 제작투자를 계획대로 진행"; 2007-01-22(2007-02-06 감사 확정 정정) 온미디어 '매출액 또는 손익구조 30% 이상 변경(자회사 OCN)': 2006 OCN 매출 140,322백만원(+39.8%)·영업이익 38,781백만원(+58.6%), 변동 주요원인 "광고시장 성장에 따른 매출액 증가"; 2006-09-18~22 해외 IR(상반기 경영현황·장기전략)과 2007-02-13 2006 연결실적 발표 공정공시가 있으나 발표 자료 원문(온미디어 홈페이지, 폐쇄)은 확인하지 못함. 어닝콜 녹취록 없음 | BF5: 완료 | BG5: 2026-10-26
A6: C003 | B6: CJ ENM | C6: 2007-06-05 | D6: CJ Music Co., Ltd. | E6: 15 | F6: True | H6: MA④ | I6: MA④ | J6: 같음 | K6: 해당 없음 | L6: 불일치 | M6: 편입 후 | N6: Closed | O6: 284.43 | P6: M-net Media Corp | Q6: CJ Corporation (KOSE:A001040) | R6: M-net Media Corp (KOSDAQ: A056200) signed an agreement to acquire CJ Music Corporation from CJ Corp. (KOSE: A001040) for approximately KRW 260 billion in stock on February 5, 2007. As per the terms of the transaction, the exchange ratio of M-net and CJ Music is 1:0.9019140. | S6: Music & Fan Entertainment | T6: Music / Artist Management | U6: MA-2 그룹 내부 재편 | W6: MA④ 그룹 내부 재편 | Y6: False | Z6: MA④ 그룹 내부 재편 | AA6: 편입 후 (CJ ENM 전신 계보: 엠넷미디어, 2011 CJ ENM 계보로 합병 — 엠넷미디어는 2011-03-01 오미디어홀딩스(CJ E&M)에 흡수합병(C008)되고 CJ E&M은 2018-07-01 CJ오쇼핑에 합병돼 현 CJ ENM이 됨). 참고: 거래 당시 엠넷미디어는 CJ㈜(20.40%, CJ미디어 포함 26.84%)가 최대주주인 CJ그룹 계열사로, 현 CJ ENM 법인(당시 CJ홈쇼핑)의 종속회사는 아니었음 | AB6: 완료 (2007-05-31 합병기일; 2007-06-04 합병등기, 2007-06-05 합병종료보고서 제출 — 원자료 date 2007-06-05는 종료보고서 날짜) | AC6: 126,664,301,610원 (합병신주 14,575,869주 × 엠넷미디어 합병가액 8,690원; = 씨제이뮤직 16,161,041주 × 본질가치 7,837.63원, 합병비율 1:0.9019140). 배정: CJ㈜ 9,196,994주(79,922백만원), CJ미디어 5,116,218주(44,460백만원), 씨제이뮤직 자기주식분 262,657주(엠넷 자기주식이 됨). 씨제이뮤직 주주가 모두 CJ 계열이라 그룹 밖으로 나간 대가는 없음 | AD6: 원자료와 불일치: 공시 기준 126,664백만원 = 136.9백만 달러 (Yahoo Finance KRW=X 2007-02-05 종가 925.15원/달러, 계산). 원자료 284.43은 같은 환율로 약 2,631억원으로 설명란 'KRW 260 billion'과 맞음. 추정: 2006-12-29 2대1 감자 전 씨제이뮤직 주식수 32,322,082주를 쓴 값 — ×0.9019140 = 29,151,738주를 합병가액 8,690원으로 평가하면 2,533억원(273.8백만 달러, 원자료와 -3.7%), 엠넷 기준주가 산술평균 9,083원으로 평가하면 2,648억원(286.2백만 달러, +0.6%). 공시상 합병 시점 씨제이뮤직 주식은 감자 후 16,161,041주였으므로 원자료 금액은 약 2배 과대 | AE6: 2007-02-05 | AF6: 기준 분류 유지(MA④): 매수자 엠넷미디어(CJ㈜ 20.40%·CJ미디어 6.44%로 CJ 계열이 최대주주)와 매도자 씨제이뮤직 주주(CJ㈜ 63.1%, CJ미디어 35.1%, 자기주식 1.8%)가 모두 CJ그룹 회사(합병결정 공시 '회사와의 관계: 계열회사'). 원자료 sellers 'CJ Corporation'만 적었으나 CJ미디어 35.1%도 매도자. 원자료 date(2007-06-05)는 합병종료보고서 제출일이고 최초 발표는 2007-02-05(이사회·합병계약·공시). 합병비율 1:0.9019140은 공시와 일치. 금액은 원자료보다 공시값이 약 절반(value_chk_usdmm 참조). 비상장 씨제이뮤직이 상장사 엠넷미디어에 합병되며 최대주주 지분이 늘어 공시상 '우회상장 해당 여부: 예'로 분류됨. 분류 해석 주의: 매도자 CJ㈜를 '그룹'으로 본 원자료 기준을 따름 — 최신 CJ 계보 규칙처럼 CJ ENM 계보로 좁히면 CJ㈜는 계보 밖이라 구조상 MA①(계보 회사 엠넷미디어가 계보 밖 CJ㈜로부터 씨제이뮤직 100% 취득)으로도 볼 수 있음(사용자 확인 필요) | AG6: C008의 선행 거래: 이 합병으로 씨제이뮤직의 음반·음원 사업과 Mnet 음악채널 사업이 엠넷미디어로 들어갔고, 엠넷미디어는 2010-11-16 결정된 CJ E&M 6사 합병에서 소멸(C008). 씨제이뮤직(DART 00525031)은 2003-02 씨제이미디어라인으로 설립, 2004-12 (구)씨제이뮤직과 합병, 2005-03-17 씨제이뮤직으로 상호 변경, 2006-09 CJ미디어의 현물출자로 Mnet 음악채널 사업부를 넘겨받음, 2006-12 2대1 무상감자. 엠넷미디어(DART 00335562, 코스닥 056200)는 1994년 설립 e-러닝·SI 회사 ㈜메디오피아테크날리지로 2002-01 코스닥 상장, 2006-07 CJ㈜·CJ미디어 제3자배정 유상증자(9,090,908주)로 최대주주가 CJ㈜로 바뀌고 같은 달 지엠기획·에이디이천엔터테인먼트를 포괄적 주식교환으로 편입(2006-09 소규모 합병), 2006-08-22 엠넷미디어로 상호 변경, 2006-09 기존 사업을 물적분할(메디오피아테크, 2006-12 매각). 2006년 엠넷 당기순손실 45,860백만원은 '합병으로 인한 무형자산 감액손실(316억원)'이 주원인(2007-01-30 손익구조변동 공시). 합병 후 엠넷미디어 반대주주 1,748,989주가 주당 9,225원(16,134백만원, 차입금)에 주식매수청구됨 — 매수자 측 현금 유출이지 대상회사 주주에 대한 대가는 아님. 회계: 합병 전후 요약재무에서 씨제이뮤직 순자산 22,094백만원을 단순합산해 자본금 7,288백만원·자본잉여금 15,375백만원으로 반영하고, 엠넷 2008 감사보고서 영업권 주석에도 2007년 합병 증가분이 없음 → 이 합병의 영업권은 없음. 공시 시점: 엠넷 매매거래정지 2007-02-05 16:18:36(장 마감 후)~2007-02-06 해제. 합병 전 회사 전망(2007-04-17 공정공시: 2007년 매출 1,210억원·영업이익 119억원)과 실제(매출 629억원·영업손실 183억원)의 괴리가 크고 회사가 정정공시로 사유를 밝힘(earnings_call_note). 조사 한계: 2006~2007년 엠넷미디어 사업보고서 일부 절은 DART 서버가 깨진 글자로 돌려줘 2010 증권신고서의 5년 요약재무를 씀. 당시 언론 보도·IR 발표자료는 찾지 못해 회사의 공정공시로 대신함 | AH6: 엠넷미디어㈜ (영문 M-net Media Corp., 코스닥 056200; CJ㈜ 20.40%·CJ미디어 6.44%가 최대주주인 CJ그룹 계열사, 옛 ㈜메디오피아테크날리지) | AI6: "음반,방송 시장에서의 경쟁력 제고와 경영효율성 증대를 통하여 시너지 효과를 극대화하고 주주가치 극대화를 추구하고자 합니다" (회사합병결정 공시 합병목적·합병신고서 합병의 목적) | AJ6: 음반·음원 기획·유통, 온라인 음악 포털(스트리밍·다운로드), 연예 매니지먼트. 2006년(제13기) 매출 22,643,185천원 중 분할·합병 후 영위사업(2006-09-23~12-31) 6,278,717천원(컨텐츠사업 2,932,387천원 + 포털사업 3,346,330천원), 나머지 16,364,468천원은 2006-09 물적분할로 넘긴 e-러닝·SI 기존사업(2007 합병신고서 엠넷미디어 매출실적). 2006년 영업손실 10,137,612천원 | AK6: 핵심 | AL6: 씨제이뮤직의 주력은 음반·음원(2006년 매출 16,922,980,862원, 66%)으로 엠넷미디어의 음반·음원·온라인 음악 사업과 같은 영역. 함께 들어온 Mnet 음악채널(방송사업 8,705,728,248원, 34%)은 음악 콘텐츠 유통 경로로 인접 영역. 그룹 정점 CJ ENM 기준으로도 음악·음악채널(Mnet)은 현 음악사업 부문의 전신이라 핵심 | AM6: 139,878,437천원 (엠넷미디어 별도, 2006-12-31; 2007 합병신고서 요약재무정보 제13기). 참고: 합병종료보고서의 2007-03-31 기준 134,993,665,460원 | AN6: 7,200,333,028천원 (상장 지배회사 CJ㈜ 및 종속회사 연결 총자산, 2006-12-31; CJ㈜ 2006 연결감사보고서). 인수 주체 엠넷미디어도 코스닥 상장사이나 지배회사는 CJ㈜. 2007년에는 CJ E&M이 없었고 당시 CJ홈쇼핑(현 CJ ENM 법인)은 이 거래와 무관 | AO6: 계산: 90.55 (126,664백만원 ÷ 엠넷미디어 총자산 139,878백만원, 2006-12-31). CJ㈜ 연결 총자산 대비 1.76. 합병 공시에 총자산대비 항목 없음 | AP6: 계산: 105.74 (126,664백만원 ÷ 엠넷미디어 자본총계 119,783백만원, 2006-12-31) | AQ6: 계산: 294,270,730,050원 (2007-02-02 종가 8,690원 × 발행주식 33,863,145주; 종가는 합병비율 평가의견의 기준주가 산정표, 주식수는 합병신고서 합병 전 발행주식수). 주의: 합병 공시가 2007-02-05 정규장 마감 후(매매정지 16:18:36)라 엄밀한 '발표 직전 거래일'은 2007-02-05이나, 그날 종가는 상장폐지 종목이라 Yahoo Finance에 없고 공시에서도 찾지 못함 | AR6: 총자산·자본은 엠넷미디어 2006-12-31 감사 재무(2007 합병신고서 20070329001139 요약재무정보). 합병가액 8,690원은 2007-02-02 종가가 산술평균가(9,083원)보다 낮아 기준주가로 쓰인 값(평가기관 우리회계법인). 신주 배정은 합병신고서 최대주주 변동표(CJ㈜ 6,909,090→16,106,084주, CJ미디어 2,181,818→7,298,036주)와 보호예수 내역(CJ㈜ 9,196,994주, CJ미디어 5,116,218주, 씨제이뮤직 262,657주)에서 확인 | AS6: KRX:056200 | AT6: 인수 주체 엠넷미디어(코스닥 056200; 2011-03 CJ E&M에 피합병돼 상장폐지라 Yahoo Finance 시세 없음). 대상 씨제이뮤직은 비상장. 그룹 정점 CJ㈜(KRX:001040)도 함께 볼 수 있음. 엠넷미디어 주권은 2007-02-05 16:18:36(정규장 마감 후) '우회상장 여부 및 요건충족 확인'으로 매매거래정지(20070205900084)됐다가 2007-02-06 해제(20070205900119, 해제사유 '합병신고서 제출(우회상장 해당)')돼 첫 반응일은 2007-02-06 | AU6: 2007-02-05 정규장 마감 후: DART 엠넷미디어 회사합병결정·합병신고서, 씨제이뮤직 회사합병결정 공시, 엠넷미디어 주권 매매거래정지(16:18:36)·2007-02-06 해제. 2006-12~2007-02 엠넷미디어 공시 목록에 관련 조회공시 없음, 사전 보도는 찾지 못함 | AV6: 2003-02: 씨제이미디어라인 설립; 2004-12: (구)씨제이뮤직과 합병; 2005-03: 씨제이뮤직으로 상호 변경; 2005-07~2006-02: 유상증자(80억원씩) 후 갑·DSP·울림·팜·H2·오렌지쇼크·플레디스·마스터플랜·스타애비뉴·원오원 등 기획사 지분 투자, 좋은콘서트 인수; 2006-05: 음악포털 Mnet.com 오픈; 2006-07: CJ㈜·CJ미디어가 엠넷미디어 제3자배정 유상증자로 26.84% 취득(최대주주 변경); 2006-09: CJ미디어 현물출자로 Mnet 음악채널 사업부 양수; 2006-12: 2대1 무상감자; 2005→2006: 씨제이뮤직 매출 1,973,050천원→25,628,709천원, 영업이익 -2,194,875천원→2,512,586천원 | AW6: 2007-04-16: 엠넷미디어 임시주총 합병 승인; 2007-04-17: 합병 반영 2007년 매출 1,210억원·영업이익 119억원 전망 공정공시; 2007-05-07~17: 반대주주 1,748,989주 주식매수청구(9,225원); 2007-05-31: 합병기일(발행주식 33,863,145→48,439,014주, CJ㈜ 33.25%·CJ미디어 15.07%); 2007-06-28: 합병신주 14,575,869주 추가상장(2009-05-30까지 보호예수, 우회상장 표시); 2007·2008: 엠넷미디어 영업권 손상(7,684·26,944백만원, 2006년 기획사 인수분으로 보임); 2008-02-29: 2007년 전망을 매출 629억원·영업손실 183억원으로 정정(음반시장 침체·포털 유료화 차질·매니지먼트 매출 순연); 2008-03-28: 영문 상호 Mnet Media Corp.로 변경; 2009-10: SC PE·CJ㈜ 대상 300억원 CB·BW 발행; 2010-12~2011-02: BW 행사·CB 전환으로 주식수 65,170,746주; 2010-11-16: 오미디어홀딩스(CJ E&M)의 엠넷미디어 흡수합병 결정(C008); 2011-03-01: CJ E&M 음악·공연 및 방송(Mnet·KM 채널) 부문으로 편입; 2016-12-01: 음악플랫폼(Mnet.com) 물적분할 → 씨제이디지털뮤직; 2018-07-01: CJ ENM 출범; 2018-10: 씨제이디지털뮤직이 ㈜지니뮤직에 흡수합병(CJ ENM 지니뮤직 지분 2024년말 15.35%); 2024: CJ ENM 음악사업(엠넷 채널 포함) 매출 702,102백만원·영업이익 30,883백만원, 지니뮤직 관계기업투자주식 손상 30,293백만원 | AX6: 해당 없음 (이 합병은 씨제이뮤직 순자산을 장부금액으로 단순합산해 자본금·자본잉여금으로 반영, 영업권 미인식 — 합병종료보고서 합병 전후 요약재무; 엠넷 2008 감사보고서 영업권 주석에도 2007년 합병 증가분 없음). 참고: 엠넷미디어 영업권 손상차손 2007년 7,683,957천원, 2008년 26,944,153천원(2008 감사보고서 주석 9; 추정: 2006년 지엠기획·에이디이천엔터테인먼트 주식교환·합병에서 생긴 영업권 — 2005년말 무형자산 585,710천원 → 2006년말 64,170,062천원, 2006년 감액손실 316억원 별도), 2008년 지분법적용투자주식 손상차손 13,073,303,878원. 후속 사업 수준 참고: Mnet.com 사업을 흡수한 지니뮤직 지분에 CJ ENM이 2024년 관계기업투자주식 손상차손 30,293백만원 인식(CJ ENM 2024 사업보고서 연결 관계기업 주석) | AY6: 동일지배 합병·그룹 내 이전으로 새 영업권·투자주식 평가가 생기지 않음 | AZ6: 2005: 1,973,050천원; 2006: 25,628,709천원 (씨제이뮤직 별도; 2006년은 음악사업 16,922,981천원 + 2006-09 양수한 Mnet 채널 방송사업 8,705,728천원) | BA6: 2007: 62,892,777천원; 2008: 118,535,379천원 (합병 후 엠넷미디어 별도, 씨제이뮤직 사업은 2007-06부터 포함); 최근(독립 법인 마지막 연도) 2010: 146,925,601,938원(포털 44,037백만원·음악 49,209백만원·방송 40,208백만원·기타 13,472백만원). 후속 사업 대리지표 — CJ E&M 음악·공연(·온라인) 부문: 2011 132,460백만원(합병 후 3~12월), 2017 음악부문 230,732백만원; CJ ENM 음악사업 2024 702,102백만원 | BB6: 2005: -2,194,875천원; 2006: 2,512,586천원 (씨제이뮤직 별도) | BC6: 2007: -18,270,619천원; 2008: -3,109,256천원 (엠넷미디어 별도); 최근(독립 법인 마지막 연도) 2010: 1,577,740,895원. CJ E&M 음악·공연 부문 2011 -847백만원, 2017 음악부문 11,778백만원; CJ ENM 음악사업 2024 30,882,579천원 | BD6: 인수 전: 씨제이뮤직 별도·K-GAAP·12월 결산(2007 합병신고서 20070329001139 씨제이뮤직 요약재무·매출실적; 2006 감사보고서 기준). 인수 후: 대상은 2007-05-31 소멸해 사업을 이어받은 엠넷미디어 별도 실적으로 대신함 — 엠넷미디어 자체의 기존 음반·포털·매니지먼트 사업이 섞여 있음. 2007~2009는 2010 CJ E&M 합병 증권신고서(20101202000223) 엠넷미디어 요약재무(천원), 2010은 엠넷미디어 감사보고서(20110310000462). 2011 이후는 CJ E&M 연결 음악·공연 부문(2014년부터 음악부문 분리 공시)과 CJ ENM 음악사업 부문(K-IFRS) — Mnet 채널은 CJ E&M 시절 방송부문, CJ ENM 2024년에는 음악사업에 포함돼 범위가 다름 | BE6: 2007-04-17 엠넷미디어 영업실적 전망 공정공시('향후 당사의 IR자료로 활용'): 합병 반영 2007년 매출 1,210억원·영업이익 119억원(합병 미반영 821억원·31억원), 근거 '방송채널의 시청율 및 점유율 상승', '컨텐츠 제작 및 공연사업등과의 시너지를 통한 제작원가 절감'; 2008-02-29 정정공시: 2007년 매출 629억원·영업이익 -183억원으로 수정, 사유 '음반시장 침체로 인하여 매출 약 70억 차질', 포털 '유료화 수입 차질 ... 약240억 차질', 매니지먼트 '약288억 차질', '매출부진에 따른 이익감소 약300억 차질'; 2009-03-05 2008년 실적 공시: '당초 영업이익 흑자전환을 기대하였으나, 연도말 금융위기에 따른 대손금 설정증가로 달성하지 못하였음'. 어닝콜 녹취록·IR 발표자료는 찾지 못함 | BF6: 완료 | BG6: 2026-10-26
A7: C004 | B7: CJ ENM | C7: 2009-12-24 | D7: On Media Corp. | E7: 11 | F7: True | H7: MA① | I7: MA① | J7: 같음 | K7: 식별 불가 | L7: 불일치 | M7: 편입 후 | N7: Effective | O7: 435.77 | P7: CJ ENM CO., Ltd. (KOSDAQ:A035760) | Q7: ORION Holdings Corp. (KOSE:A001800) | R7: CJ O Shopping Co., Ltd. (KOSE: A035760) agreed to acquire a 55.17% stake in On Media Corp. from Orion Corporation (KOSE: A001800), Tam Cheol-gon and other shareholders for approximately KRW 430 billion in cash on December 24, 2009. CJ O Shopping will offer KRW 6669 per share of On Media. The offer price represents a 71% premium to the On Media’s closing price of December 23, 2009. If South Korea's Fair Trade Commission doesn't approve of the majority stake purchase, then CJ O Shopping is expected to acquire about 15% stake of On Media. The deal is subject to regulatory approval and approval of South Korea's Fair Trade Commission. The transaction was approved by the Board of Directors. The deal is expected to close by the first half of 2010. As of May 31, 2010, the deal was approved by the South Korea's Fair Trade Commission. As of June 8, 2010, Orion Corporation sold it share in On Media Corp. HSBC Bank plc acted as financial advisor to Orion Corporation. Morgan Stanley acted as financial advisor and Kpmg Samjong Accounting Corporation acted as a financial due diligence to CJ O Shopping. | S7: Media Platforms | T7: Broadcasting Channel | U7: MA-1 그룹이 매수자 | V7: 과반 인수(≥50%) | W7: MA① 경영권 인수 | Y7: False | Z7: MA① 경영권 인수 | AA7: 편입 후 (매수자 ㈜씨제이오쇼핑은 현 CJ ENM 법인 자체 — DART 고유번호 00265324, 2018-07-01 CJ E&M 흡수합병 후 CJ ENM으로 사명 변경. 대상 온미디어는 이 거래로 2010-05-28 CJ오쇼핑의 자회사로 편입(지주회사의 자회사 편입 공시), 2010-06-08·06-30 대금지급으로 소유 확정) | AB7: 완료 (2010-06-30; 공정위 기업결합 승인통보 2010-05-28, 오리온 및 특수관계인 40.18% 대금지급·주식양수 2010-06-08, 외국계 3개 펀드 14.99% 대금지급 2010-06-30 — 합병등종료보고서의 자산양수도 완료일 2010-06-30) | AC7: 434,479,300,000원 (온미디어 보통주 65,148,910주·55.17%, 평균 주당 6,669원. 매도자별: ㈜오리온 및 특수관계인 5인 47,448,210주(40.18%) 345,976백만원(주당 약 7,292원, 경영권 프리미엄 포함); Tabimax SGPS Lda 8,459,598주 42,298백만원·Capital International GEM PE Fund 7,392,882주 36,964백만원·New Asia East Investment Fund 1,848,220주 9,241백만원(이상 주당 5,000원, 소계 88,503.5백만원). 현금, 계약 시 위약금 346억원 예치) | AD7: 원자료와 불일치: 434,479백만원 = 370.38백만 달러 (계산: Fed H.10 2009-12-24 1,173.07원/달러). 대금 지급일 환율로 나누면 352.87백만 달러(오리온분 2010-06-08 1,233.99원 → 280.37 + 외국계분 2010-06-30 1,220.85원 → 72.49). 원자료 435.77은 어느 기준으로도 재현되지 않으며 설명란 'approximately KRW 430 billion'을 원/달러 약 987원으로 나눈 값에 해당해 환산 오류로 보임 | AE7: 2009-12-24 | AF7: 기준 분류 유지(MA① 경영권 인수): CJ오쇼핑이 지분이 없던 온미디어의 55.17%를 사 최대주주·경영권을 처음 확보. 원자료 buyers 'CJ ENM CO., Ltd. (KOSDAQ:A035760)'는 현 사명 기준 표기이며 당시 인수 주체는 ㈜씨제이오쇼핑(같은 법인 00265324) — 다른 CJ 계열사(CJ㈜·CJ미디어 등)가 아님을 공시로 확인. 원자료 sellers 'ORION Holdings Corp.'는 당시 ㈜오리온(현 오리온홀딩스)이며 담철곤 외 4인과 외국계 펀드 3곳도 매도자. 설명란의 'KRW 6669 per share'는 평균값으로 실제는 오리온 측 약 7,292원·외국계 5,000원의 이중 가격이며, '71% premium'은 평균가 기준(6,669/3,910원 = 70.6%; 외부평가 기준 오리온 측 86.5%·기타 27.88%). 'approved by FTC as of May 31, 2010'은 공정위 승인통보 2010-05-28·발표 2010-05-30이 정확함. 금액 435.77백만 달러는 환산 오류로 보여 370.38로 정정 제안 | AG7: 온미디어 계보(CJ-B)의 중심 거래. 선행: C002(2006, 오리온 시절 OCN 증자). 후행: C009(2010-11 결정·2011-03-01 오미디어홀딩스=CJ E&M이 온미디어를 흡수합병하며 잔여 지분 정리 — 같은 날 C005~C008 CJ E&M 출범 합병과 한 건), C010(2010-12 온게임넷 7%), C011·C012(2013-12 바둑TV·OCN 흡수합병). 인수 주체 문제: 거래는 CJ오쇼핑이 했지만 2010-09-01 CJ오쇼핑 인적분할로 온미디어 지분 55.17%가 신설 ㈜오미디어홀딩스(2010-12-30 CJ E&M으로 사명 변경)로 넘어가 이후 성과는 CJ E&M 쪽에서 나타남; CJ오쇼핑과 CJ E&M은 2018-07-01 다시 합쳐져 현 CJ ENM이 되므로 계보상 같은 그룹 안. 매각 경과: 오리온은 2009-04 매각설 조회공시에 '검토 중', 2009-09-04 '매각하지 않기로 결정' 통보, 2009-12-10 CJ의 인수 제안 확인 후 2009-12-24 계약 — 인수가격 재협상 가능성이 당시 분석(신한금융투자)에서 거론됨. 자금: 자기자금 2,285억(2009말 보유현금 약 2,500억, 2009 회사채 1,300억 포함)·차입 600억(국민은행·농협)·기타 1,460억(공모사채 600억, 자회사 CJ헬로비전드림씨티방송 유상감자 대금 약 860억). 공시 불일치: 2009-12-24 타법인주식취득결정은 '공정거래위원회 신고대상 여부: 미해당'이라 적었으나 실제로는 공정위 기업결합심사를 거침(2010-06-03 대량보유보고서·언론 보도). 합병등종료보고서의 '1주당 액면가액 5,000원'은 온미디어 액면 500원(2006 분할)의 오기. 사후 가치 시사점: 평균 취득가 6,669원 대비 2010-11 합병가액 3,535원, 2011-01-28 CJ E&M의 블록세일 가격 4,900원(10%, 578.2억원)으로 시장가는 취득가를 크게 밑돌았음(승자의 저주 검토 자료). 방통위 최다액출자자 변경 승인일 자체는 찾지 못함(2010-02-09 심사계획 보도만 확인, 2010-06-03 대량보유보고서는 '최종 정부기관(방통위,공정위) 승인 후 장외 매매계약 확정'이라고만 기재) | AH7: ㈜씨제이오쇼핑 (CJ O Shopping, 코스닥 035760; 현 CJ ENM 법인. 최대주주 CJ㈜ 39.96%(2010-06). 당시 TV홈쇼핑·카탈로그·인터넷몰 사업자이자 MSO ㈜씨제이헬로비전의 모회사) | AI7: "홈쇼핑 사업 경쟁력 강화 등" (타법인주식및출자증권취득결정 취득목적) / "CJ오쇼핑의 차별화를 위한 핵심 역량의 강화는 물론, 기존 사업 기반의 확대와 보유 자산의 가치 증대에도 기여할 것으로 판단" (주요사항보고서 자산양수도의 배경) / "미디어에 쇼핑을 접목한 '컨버전스(Convergence)'모델을 통해 새로운 성장 동력을 만들어간다는 전략의 일환" (주요사항보고서) / "유통과 미디어를 결합해 다른 경쟁사와 차별화시키겠다" (CJ오쇼핑, 머니투데이 2009-12-24) | AJ7: 케이블 TV홈쇼핑 중심의 무점포 유통(TV홈쇼핑·카탈로그·인터넷 통신판매). 2008 별도 영업수익 542,420백만원·영업이익 87,251백만원, TV홈쇼핑 취급고 점유율 25.1%(2008). 연결로는 SO 자회사 CJ헬로비전(260만 가입자) 포함 2008 매출 963,557백만원·영업이익 119,012백만원(2009 사업보고서 요약재무·사업의 내용) | AK7: 인접 | AL7: CJ오쇼핑은 홈쇼핑 채널을 공급하는 PP이자 SO(CJ헬로비전)를 가진 유통·플랫폼 회사로, 일반 PP 콘텐츠(MPP 채널)는 같은 유료방송 가치사슬의 다른 단계 — 공시도 '컨버전스'·'MSP(MSP+MPP) 사업모델'(원문 표기 그대로; MSO+MPP의 오기로 보임)과 SO 가입자 320만 확보를 내세움. 온미디어의 SO 4곳(56만 가입자)은 CJ헬로비전과 같은 사업이지만 매출 비중이 작음. 인수 직후 지분이 미디어 전문 법인(오미디어홀딩스→CJ E&M)으로 넘어갔고, 현 CJ ENM(미디어플랫폼·영화드라마·음악·커머스) 기준으로는 TV채널 사업의 핵심 축이 됨 | AM7: 969,862,669,601원 (CJ오쇼핑 별도, 2008-12-31; 주요사항보고서·타법인주식취득결정 '최근 사업연도말 자산총액') | AN7: acq_total_assets와 같음 (인수 주체 CJ오쇼핑이 상장 지배회사 자신). 참고: CJ오쇼핑 연결 총자산 1,669,955,092천원 (2008-12-31, 2009 사업보고서 요약연결재무정보 제15기); 거래금액/연결총자산 26.0%(계산) | AO7: 44.80 | AP7: 86.97 | AQ7: 계산: 834,610,832,600원 (발표 직전 거래일 2009-12-23 종가 75,800원 × 발행주식 11,010,697주(2009-12-31 자본금 55,053,485,000원/액면 5,000원)). 종가는 Yahoo Finance 035760.KQ 수정주가 104,635.53원을 조정계수 1.380416으로 나눠 복원 — 계수는 2009년 12월 Yahoo 최고·최저 종가(118,025.57·99,942.12)를 2009 사업보고서의 12월 종가 기준 최고 85,500원·최저 72,400원과 맞춰 산출(두 값 모두 1.380416으로 일치). 발표일 2009-12-24 종가 78,200원(+3.2%) | AR7: 총자산·자기자본(499,578,002,714원)·비율은 2009-12-24 타법인주식및출자증권취득결정(20091224900008)과 2009-12-28 주요사항보고서(20091228000114) 기재값(분모 2008-12-31 별도). 연결 총자산은 2009 사업보고서(20100331000039). 시가총액은 복원 종가 × 2009말 발행주식수(계산) | AS7: KRX:035760 | AT7: 인수 주체 CJ오쇼핑(코스닥 035760, 현 CJ ENM — Yahoo 시세는 2010-09 인적분할·이후 주식배당 등을 소급 조정한 값이라 원래 종가는 1.380416으로 나눠야 함, 2009-12 기준). 대상 온미디어도 유가증권시장 상장사(KRX:045710, 2011-03 합병으로 상장폐지·Yahoo 시세 없음): 2009-12-23 종가 3,910원(외부평가 기준주가표), 시가총액 461,763,140,900원(계산, 118,097,990주), 발표 후 상한가·시가총액 한때 5,300억원 이상(머니투데이). 매도자 ㈜오리온(KRX:001800)도 분석 가능. 사전 반응: 2009-09-07 매각 무산 보도에 온미디어 −2.34%·CJ오쇼핑 +2.42%(뉴스토마토) | AU7: 2009-04-29: 거래소의 온미디어 '최대주주 지분매각설' 조회공시 요구 → 04-30 답변(미확정, 최대주주가 매각 검토 중); 2009-06-22: CJ오쇼핑 자율공시 '온미디어 인수 검토의 건'(확인일 06-19, 07-17·08-17 재공시); 2009-09-04: 온미디어 '오리온이 매각하지 않기로 결정' 통보 공시(부인); 2009-12-10: 'CJ그룹으로의 피인수설' 조회공시 → 답변(오리온이 CJ그룹으로부터 인수의향과 가격 제안을 받음, 미확정); 2009-12-24: 이사회 결의·계약 및 공시 | AV7: 2000-06-15: 온미디어 설립(오리온그룹 지주회사, OCN 50.48%·바둑TV 53.47% 현물출자); 2000-10: 투니버스·온게임네트워크 지분 취득; 2000-12~2001-09: 동구·전남동부·서남·영동·수성·서대구 등 SO 지분 취득; 2004-04: 투니버스 흡수합병(사업지주회사); 2006-07-03: 유가증권시장 상장; 2007~2009: 온미디어 연결 매출 316,356→312,917→281,091백만원, 연결 영업이익 63,041→22,182→24,002백만원(2008 급감); 2008: MPP 매출 점유율 CJ 20.8%(1위)·온미디어 11.1%(2위); 2009-04-29: 매각설 조회공시; 2009-06-22: CJ오쇼핑 인수 검토 공시; 2009-09-04: 오리온 매각 철회 통보; 2009-10-01: 온미디어 8개 채널 SK브로드밴드 IPTV 공급계약(경쟁 IPTV에 채널 공급); 2009-12-10: CJ 제안 확인; 2009-12-12: 외부평가(지성회계법인) 계약 — DCF 주당 4,846~7,406원 | AW7: 2010-02-09: 방통위 심사계획(최다출자자 변경·소유제한 검토) 보도; 2010-05-28: 공정위 최종 기업결합심사 승인통보(조건부 — 경쟁 다채널유료방송사업자, 특히 IPTV에 정당한 이유 없이 콘텐츠 동등 접근 기회 제공, 2013년 말까지; 결합 후 PP 점유율 31.9%, 영화·생활여성 100%·만화 82%), CJ오쇼핑 자회사 편입; 2010-06-08: 오리온 측 40.18% 대금지급, 최대주주 변경; 2010-06-10: CJ오쇼핑 유통/투자부문 인적분할 결정(0.55:0.45); 2010-06-30: 외국계 14.99% 대금지급(자산양수도 완료), 온미디어 담철곤·조경민 사임·김성수 단독대표; 2010-09-15: 분할신설 ㈜오미디어홀딩스 설립등기(분할기일 09-01), 온미디어 최대주주가 오미디어홀딩스로 변경; 2010-10-15: 오미디어홀딩스 코스닥 재상장; 2010-10-27: 이플레이온 청산 결정; 2010-11-16: 온미디어 등 5사 합병 결정(C009); 2010-12-07: CJ E&M 합병설명회 — 2011 통합법인 매출 13,970억·영업이익 1,550억원, 방송사업 2011 매출 6,978억·영업이익 703억원 전망, 온미디어 지분 최대 15% 매각·디지틀온미디어·SO 4사 매각 계획; 2010-12-30: 오미디어홀딩스→씨제이이앤엠 사명 변경; 2011-01-28: CJ E&M이 온미디어 11,800,000주(10.0%)를 주당 4,900원(578.2억원)에 블록세일(재무구조 개선); 2011-02-22: 디지틀온미디어 지분 전량 235억원 매각; 2011-03-01: 온미디어 흡수합병·소멸(해산등기 03-03); 2011: CJ E&M 방송부문 매출 6,358억·영업이익 474억원(전망 대비 미달); 2012-03-14: 옛 온미디어 SO 4사(영동·대구수성·대구동구·아라방송) 지분 전량을 CJ헬로비전에 1,697억원 매각('비핵심 사업에 대한 사업구조조정', 자산양수도 완료 2012-05-30); 2013-12-01: OCN·온게임넷·바둑TV 흡수합병(C011·C012); 2018-07-01: CJ오쇼핑이 CJ E&M 흡수합병, CJ ENM 출범; 2025: CJ ENM 미디어플랫폼 부문 매출 1조 3,416억원·영업이익 13억원 | AX7: 온미디어 인수 영업권 자체의 손상은 확인 안 됨. 근거: 오미디어홀딩스(CJ E&M) 2010 연결감사보고서(K-GAAP) 영업권 기초 184,355,735천원(2010-09-01)→기말 181,257,320천원(상각 3,098,415천원만, 손상 없음) — 온미디어 인수로 생긴 영업권과 온미디어 자체 영업권이 섞인 금액으로 보임(추정: 오미디어홀딩스의 유일한 자회사가 온미디어); K-IFRS 전환 뒤 CJ E&M 영업권은 방송사업부문 등 현금창출단위에서 손상검사(2013·2017 연결 주석), 영업권 손상은 2013 957,306천원·2017 853,984천원 정도로 대상 미특정·소액; CJ ENM 2025 사업보고서 연결 주석의 영업권 현금창출단위 표상 미디어플랫폼사업부문 영업권은 2024말 376,778,468천원 → 2025말 371,615,748천원(−5,162,720천원, 변동 사유는 표에 부문별로 나오지 않음); 영업권 손상 합계는 2025 19,940,683천원·2024 38,388,927천원이나 현금창출단위별 배분이 표에 드러나지 않아 온미디어 계보 채널 사업과의 관련을 판단할 수 없음. 2014~2016·2018~2023 연도별 주석은 대조하지 않음 | AY7: 2010 영업권 상각만 있고 손상 없음, 이후 방송·미디어플랫폼 현금창출단위에 묶여 온미디어 몫을 알 수 없음 | AZ7: 2008: 연결 312,917백만원 (별도 75,837백만원); 2009: 연결 281,091백만원 (별도 67,746백만원) | BA7: 2010: 온미디어 연결 260,354,763,959원 (별도 73,556,536,273원; 마지막 독립 회계연도); 2011: CJ E&M 방송부문 635,789백만원(합병기일 3월 이후, CJ미디어·엠넷 채널 포함); 2012: CJ E&M 방송부문 764,151백만원; 최근 2025: CJ ENM 미디어플랫폼 부문 1,341,617백만원(외부매출; 부문간 포함 1,500,699백만원). 참고: 2010-12-07 합병설명회 방송사업 전망 2011 6,978억·2012 7,523억원 | BB7: 2008: 연결 22,182백만원 (별도 9,346백만원); 2009: 연결 24,002백만원 (별도 18,685백만원) | BC7: 2010: 온미디어 연결 21,799,200,936원 (별도 15,701,866,969원); 2011: CJ E&M 방송부문 47,394백만원; 2012: 44,554백만원; 최근 2025: CJ ENM 미디어플랫폼 부문 1,332백만원(1,332,256천원). 참고: 전망 2011 703억·2012 765억원 | BD7: 인수 전·2010은 온미디어 K-GAAP 12월 결산(2008·2009: 2009 사업보고서 20100401001044 요약재무·요약연결재무; 2010: 2010 감사보고서 20110331002850·연결감사보고서 20110426000457). 2011년 이후 온미디어는 법인이 없어 CJ E&M 사업보고서 '사업부문별 요약 연결재무현황'의 방송부문(K-IFRS 연결; 2011: 20120330002738 — 합병소멸법인 1~2월 실적 제외, 2012: 20130401001853)과 CJ ENM 2025 사업보고서(20260318001469) 영업부문 주석의 미디어플랫폼사업으로 대신함. 방송부문에는 옛 CJ미디어(tvN 등)·엠넷 채널이, 미디어플랫폼에는 티빙 등이 포함돼 온미디어 단독 성과가 아니며 2010 연결은 9월 이후 SO 매각 계획 등 구조 변화가 있음 | BE7: CJ E&M 2012·2013 사업보고서 '합병등 전후의 재무사항 비교표'(2011-03 합병): 통합 CJ E&M 매출 예측 1,397,000·1,661,000 / 실적 1,279,186(괴리 8%)·1,394,585(16%)백만원, 영업이익 예측 155,000·189,000 / 실적 75,420(51%)·38,947(79%) — "종편출범에 따른 경쟁비용 증가, 킬러콘텐츠 확보 및 제작역량 강화를 위한 콘텐츠 투자 확대 및 게임사업부문의 역성장으로 인해 예측치보다 저조한 실적"; 2010-06-08 온미디어 기관 대상 IR(1:1): '온미디어 최대주주 변경 관련 주요 경영현황 설명', 안건에 '최대주주 변경에 따른 조직 안정화를 위한 일회성 비용' 포함(IR 안내공시; 자료 원문은 폐쇄된 온미디어 홈페이지라 미확인); 2010-12-07 CJ E&M 합병 설명회(공정공시): 통합법인 2011 매출 13,970억·영업이익 1,550억원, 방송사업 2011 매출 6,978억·영업이익 703억원 전망, 근거로 'OSMU(One Souce Multy Use)강화', '컨텐츠 구매 경쟁력 강화를 통한 비용 절감' — 실제 2011 CJ E&M 연결 매출 11,431억·영업이익 701억, 방송부문 6,358억·474억원으로 전망 미달; 2011 사업보고서 경영진단: '방송 부문의 콘텐츠 투자 … 투자비용이 반영되어 영업이익은 701억원'; 2009-12-24 머니투데이: CJ오쇼핑 측 '보유 현금이 많고 자회사 배당금도 들어올 예정', 애널리스트 'CJ오쇼핑에는 별다른 시너지가 없으나 CJ미디어와는 시너지'. CJ오쇼핑 어닝콜 녹취록은 찾지 못함 | BF7: 완료 | BG7: 2026-10-26
A8: C005 | B8: CJ ENM | C8: 2010-11-16 | D8: CJ Entertainment Inc. | E8: 29 | F8: True | G8: C005 | H8: MA④ | I8: MA④ | J8: 같음 | K8: 해당 없음 | L8: 불일치 | M8: 편입 후 | N8: Closed | O8: 110.18 | P8: CJ E&M Corporation | Q8: CJ Corporation (KOSE:A001040) | R8: O Media Holdings Co., Ltd. (KOSE: A130960) signed a statuary merger agreement to acquire CJ Entertainment Inc. from CJ Corp. (KOSE: A001040) for approximately KRW 100 billion in stock on November 16, 2010. The exchange ratio for the transaction is 1: 1.1731389. O Media Holdings Co., Ltd. will survive and CJ Entertainment Inc will be dissolved on closing of the transaction. O Media Holdings Co., Ltd. also signed agreement to acquire remaining 44.83% stake in On Media Corp. (KOSE: A045710), M-net Media Corp, CJ Internet Corp. and CJ Media Inc. The deal is expected to close on March 1, 2011. Lee & Ko acted as legal advisor for the transaction. Gene Park and Craig Oh of WOORI Investment & Securities Co. Ltd. and Morgan Stanley acted as financial advisor for O Media Holdings Co., Ltd. Hyundai Securities Co., Ltd. acted as financial advisor for CJ Corp. Sang Gon Kim and Jun Taek Lee of Lee & Ko acted as legal advisors for O Media Holdings Co., Ltd. and acquire CJ Entertainment Inc. | S8: Content Production & Investment | T8: Content Investment / Distribution | U8: MA-2 그룹 내부 재편 | W8: MA④ 그룹 내부 재편 | Y8: False | Z8: MA④ 그룹 내부 재편 | AA8: 편입 후 (CJ ENM 전신 계보: ㈜오미디어홀딩스(2010-12-30 씨제이이앤엠㈜으로 상호 변경, 이 합병의 존속법인 CJ E&M 자체), 2018 CJ ENM 계보로 합병 — 2018-07-01 ㈜씨제이오쇼핑이 씨제이이앤엠㈜을 흡수합병하고 ㈜씨제이이엔엠으로 사명 변경, 증권발행실적보고서 20180702000188). 참고: 거래 당시 매수자는 CJ㈜가 최대주주(39.94%)인 CJ 계열 코스닥 상장사로, 현 CJ ENM 법인(당시 CJ오쇼핑)의 종속회사는 아니었음(2010-09-15 CJ오쇼핑 미디어사업 투자부문에서 인적분할된 자매회사). 대상 씨제이엔터테인먼트는 CJ㈜ 100% 자회사로 이 합병(2011-03-01)으로 CJ E&M에 편입 | AB8: 완료 (2011-03-01 합병기일; 2011-03-03 합병·해산등기, 합병신주 32,971,307주 2011-03-21 교부·2011-03-22 상장 예정 — 증권발행실적보고서) | AC8: 102,590,976,400원 (계산: 씨제이엔터테인먼트 3,000,000주 × 1.1731389 = 합병신주 3,519,416주 × 오미디어홀딩스 합병가액 29,150원; = 주당 합병가액 34,197원 × 3,000,000주 102,591,000,000원). 전량 CJ㈜에 배정돼 그룹 밖으로 나간 대가는 없음. 원자료 설명란 'approximately KRW 100 billion'과 일치 | AD8: 원자료와 불일치: 102,591백만원 = 90.1백만 달러 (Yahoo Finance KRW=X 2010-11-16 종가 1,138.10원/달러, 계산). 원자료 110.18은 같은 환율로 약 1,254억원으로, 원자료 자체 설명란('KRW 100 billion')과도 맞지 않음 | AE8: 2010-11-16 | AF8: 기준 분류 유지(MA④): 매수자 오미디어홀딩스(CJ㈜ 39.94%)와 매도자 CJ㈜(씨제이엔터테인먼트 지분 100%)가 모두 CJ그룹 회사이고 대가(합병신주)도 전부 CJ㈜가 받음. 원자료 buyers 'CJ E&M Corporation'은 합병 당시 사명 ㈜오미디어홀딩스(DART 00838421, 2010-12-30 씨제이이앤엠㈜으로 상호 변경)로, 현 CJ ENM 법인(00265324, 옛 CJ오쇼핑)과 다른 법인. 설명란의 비율 1:1.1731389와 2011-03-01 완료 예정은 공시와 일치. 설명란의 자문사(Lee & Ko, 우리투자증권·Morgan Stanley, 현대증권)는 공시에서 확인하지 못함(공시에는 외부평가기관 삼일회계법인만 기재). 같은 날 같은 매수자의 C006(CJ인터넷)·C007(CJ미디어)·C008(엠넷미디어)·C009(온미디어, 다른 묶음)와 한 합병 계약의 대상회사별 행 — 이중 집계 아님, 합산 시 합병신주 총 32,971,307주 | AG8: C001의 후속 거래: 대상 씨제이엔터테인먼트㈜(DART 00576309)는 2006-04-10 구 CJ엔터테인먼트(현 CJ EH, CJ㈜에 흡수)에서 물적분할로 신설된 영화 배급·투자·제작 법인(C001). 합병가액 34,197원은 비상장사라 외부평가기관 삼일회계법인이 본질가치(자산가치 40,264원·수익가치 30,152원, 1:1.5 가중)로 산정. 주식매수청구는 없었음(유일 주주 CJ㈜). 합병 후 CJ E&M 영화사업부문(대표 김정아)이 됐고, 영화부문 실적은 공연사업 포함 범위가 해마다 달라짐(2011~2013 음악/공연, 2014년부터 공연 별도). 어닝콜 녹취록은 찾지 못해 earnings_call_note는 실적 발표 기사·사업보고서 MD&A로 대신함 | AH8: ㈜오미디어홀딩스 (O Media Holdings Co., Ltd., DART 00838421, 코스닥 130960; 2010-09-15 ㈜씨제이오쇼핑의 미디어사업 투자부문이 인적분할돼 설립된 순수지주회사로 자회사 온미디어 55.17% 보유, 최대주주 CJ㈜ 39.94%(2010-11-16)→45.38%(2011-01-27); 2010-12-30 씨제이이앤엠㈜(CJ E&M)으로 상호 변경 — 합병 존속법인이 곧 CJ E&M) | AI8: "경영효율성을 증대시키고 엔터테인먼트사업(영화, 음악, 게임)과 미디어사업을 통합하여 시너지 효과를 극대화하고 규모의 경제를 갖추어 세계적 회사로 성장하기 위하여 합병하기로 결정함" (회사합병결정 공시 합병목적) / "① OSMU(One-Source-Multi-Use) 실현 가능 ② 광고 영업 효율화, 구매력 강화, 시너지 마케팅 활성화 ③ 세계시장 진출을 위한 규모의 경제 확보, 대규모 / 지속가능한 투자여력 확보" (주요사항보고서 예상 시너지) / "그룹이 목표로 하고 있는 콘텐츠 사업의 글로벌화와 계열사간 시너지 극대화를 위해 합병을 결정하게 됐다" (CJ 측, 이투데이 2010-11-16) | AJ8: 순수지주회사 — 자회사 ㈜온미디어(55.17%, 투니버스·OCN 등 케이블 방송채널사용사업자) 지분만 보유하고 영업수익은 지분법이익(증권신고서 투자위험요소 '순수지주회사로 영업수익은 지분법이익으로 구성'), 임직원 10명(2010-11 기준). 실질 사업은 온미디어의 케이블 PP: 2009년 온미디어 별도 매출 67,746백만원·자산 449,318백만원 | AK8: 인접 | AL8: 인수 주체(실질 사업은 자회사 온미디어의 케이블 영화·애니메이션 채널 OCN·투니버스 등)에게 영화 투자·배급은 같은 콘텐츠 가치사슬의 상류(영화 판권이 영화채널에 공급됨)라 인접 영역. 합병 공시도 OSMU를 첫 시너지로 꼽음. 그룹 정점 CJ ENM 기준으로는 영화가 현 영화드라마 부문의 전신이라 핵심 | AM8: 477,015백만원 (오미디어홀딩스 별도, 2010-09-30; 증권신고서 당사회사 요약·증권발행실적보고서 합병 전 요약재무). 설립 개시재무상태표(2010-09-01) 474,852,301,036원. 참고: 2010-12-31 별도 473,527,264,185원, 연결(K-IFRS) 810,677,928천원 | AN8: acq_total_assets와 같음 (인수 주체 오미디어홀딩스=CJ E&M이 상장 지배회사 자신; 2010-09-15 설립이라 직전 회계연도말이 없음). 참고: 첫 결산 2010-12-31 연결 총자산 810,677,928천원(K-IFRS 재작성, CJ E&M 2011 사업보고서), 합병 6사 단순합산 1,691,841백만원(2010-09-30, 증권발행실적보고서 '합병 후' 개략 연결) | AO8: 계산: 21.51 (102,591백만원 ÷ 오미디어홀딩스 별도 총자산 477,015백만원, 2010-09-30). 합병 6사 단순합산 총자산(1,691,841백만원) 대비 6.06. 공시에 비율 항목 없음 | AP8: 계산: 33.97 (102,591백만원 ÷ 오미디어홀딩스 별도 자본총계 302,024백만원, 2010-09-30) | AQ8: 계산: 144,533,191,550원 (발표 직전 거래일 2010-11-15 종가 29,150원 × 발행주식 4,958,257주; 종가는 주요사항보고서 합병가액 산정표, 주식수는 증권신고서 당사회사 요약). 2010-10-15 재상장 직후라 유통 이력이 한 달뿐임 | AR8: 인수 주체 규모는 오미디어홀딩스 2010-09-30 별도 재무(증권신고서 20101202000223, 증권발행실적보고서 20110310000585), 거래금액은 합병가액 29,150원 × 대상회사별 합병신주(합병기일 주식수 × 합병비율, 단주 버림, 계산). 합병 주요사항보고서(20101116000288)에는 총자산·자기자본 대비 항목이 없어 직접 계산함. 합병 후 CJ E&M 규모(6사 단순합산 1,691,841백만원) 대비 비율도 함께 적음 | AS8: KRX:130960 | AT8: 인수 주체 오미디어홀딩스=CJ E&M(코스닥 130960, 2018-07 CJ오쇼핑 합병으로 상장폐지돼 Yahoo Finance 시세 없음). 2010-11-16 장 마감 후 공시·16:24 거래정지·11-17 휴장, 2010-11-18 재개라 첫 반응일은 2010-11-18. 대상 씨제이엔터테인먼트는 비상장. 그룹 지주회사 CJ㈜(KRX:001040)도 함께 볼 수 있음 | AU8: 2010-11-16 장 마감 후: DART 회사합병결정·주요사항보고서(합병결정)·각 소멸회사 회사합병결정 공시와 CJ그룹 발표(이투데이 입력 16:14). 오미디어홀딩스 주권은 16:24 우회상장 여부 확인을 이유로 매매거래정지 후 2010-11-18 재개(우회상장 미해당), CJ인터넷(16:20)·엠넷미디어(16:22) 주권은 당일 장 종료까지만 정지. 발표 전 관련 조회공시·사전 보도는 찾지 못함(2010-09~11 공시 목록, 웹 검색 2회) | AV8: 2000-04: 구 씨제이엔터테인먼트㈜가 ㈜제일제당 영화사업부를 영업양수(2010 합병 증권신고서 연혁표); 2006-04: 구 CJ엔터테인먼트에서 물적분할로 설립(CJ㈜ 100%, C001); 2006-12: <타짜> 685만; 2007-08: <화려한 휴가> 730만·<트랜스포머> 750만; 2008-08: <좋은놈 나쁜놈 이상한놈> 688만; 2009-08: <해운대> 1,152만; 2009-11: 일본 T-JOY와 합작 선포; 2009-12: 합법 다운로드 업체 엠바로 설립; 2010-04: 일본 합작법인 CJEJ 설립; 2010-10-25: 삼일회계법인과 합병가액 평가 계약; 2009→2010: 매출 166,147→163,080백만원, 영업이익 9,722→8,329백만원 | AW8: 2010-12-30: 양사 주총 합병 승인·오미디어홀딩스 CJ E&M으로 상호 변경; 2011-03-01: 합병, CJ E&M 영화사업부문(대표 김정아); 2011: 영화부문 매출 166,784·영업이익 5,834백만원(3~12월); 2012: 218,960·9,220백만원; 2014: 공연 분리 후 영화 211,318·-3,975백만원; 2015: CJ E&M 판권 손상 95,154백만원(방송·영화 판권); 2016: 영화 189,551·-23,874백만원; 2017: 198,667·-9,044백만원; 2018-07-01: CJ오쇼핑이 CJ E&M 흡수합병, CJ ENM 출범; 2024: CJ ENM 영화드라마사업부문 매출 1,704,683백만원·영업손실 26,925백만원(스튜디오드래곤·Fifth Season 포함) | AX8: 해당 없음 (이 합병으로 영업권·투자주식 미인식: CJ E&M 2011 사업보고서 — '지배회사인 CJ 주식회사의 동일 지배 하에 있는 종속회사 간 합병'으로 피합병법인 자산·부채를 장부금액으로 승계, 합병대가와 순자산 차이는 자본잉여금에 가감). 후속 사업 수준 참고: CJ E&M 2015년 판권 손상차손 95,154백만원(2015 사업보고서 무형자산 주석 '판권 중 미래현금흐름의 발생가능성이 높지 않은 판권'; 영화·방송 등 부문별 귀속은 공시되지 않음), 2014년 판권 손상 7,556,919천원·ImaginAsian 영업권 손상 3,072,325천원(2015 사업보고서 무형자산 주석 전기 표). CJ E&M 2015 사업보고서 영업권 손상검사 가정 표의 CGU는 방송사업부문·음악사업부문 등이며 영화부문은 없음 | AY8: 동일지배 합병·그룹 내 이전으로 새 영업권·투자주식 평가가 생기지 않음 | AZ8: 2009: 166,147,408,998원; 2010: 163,080,002,913원 (씨제이엔터테인먼트 별도) | BA8: 2011(합병 후 3~12월): 166,784백만원; 2012: 218,960백만원 (CJ E&M 연결 영화부문); 최근: 2017 198,667백만원(CJ E&M 마지막 연도), CJ ENM 영화드라마사업부문 2024 1,704,683백만원(드라마 제작·해외 스튜디오 포함으로 범위 다름) | BB8: 2009: 9,721,771,839원; 2010: 8,329,368,008원 (씨제이엔터테인먼트 별도) | BC8: 2011: 5,834백만원; 2012: 9,220백만원 (CJ E&M 영화부문); 최근: 2017 -9,044백만원, CJ ENM 영화드라마 2024 -26,924,539천원 | BD8: 인수 전: 씨제이엔터테인먼트 별도·K-GAAP·12월 결산 감사보고서(2010 감사보고서 20110331003203, 2009는 같은 보고서 전기). 인수 후: 2011-03-01 소멸해 CJ E&M 연결 '영화부문'(K-IFRS, 사업보고서 사업부문별 요약 연결재무현황; 2011년은 합병소멸법인 1~2월 제외, 2011~2013 공연 일부는 음악/공연부문)으로 대신하고, 최근 연도는 CJ ENM '영화드라마사업'(2024 사업보고서 영업부문 주석)을 참고로 적음 — 2016년 스튜디오드래곤 분할·2022년 Fifth Season 인수 등으로 범위가 달라 직접 비교 불가 | BE8: 2011-02-28 출범(뉴스토마토): 영화부문은 '투자·배급 중심에서 제작 역량 강화로 재편', 2015년 매출 중 영화 비중 17% 목표; 2011 사업보고서(MD&A): 영화부문 '배급사별 관객 점유율에서 지난 수년간 지속적으로 시장점유율 1위', 매출 1,668억원; 2013-02-06(아이뉴스24): 2012년 영화 매출 2,190억원, 매출·영업이익 각각 14%·109% 증가(흥행작·VOD 부가판매). 어닝콜 녹취록은 찾지 못함 | BF8: 완료 | BG8: 2026-10-26
